Workbook
Name A.: IF('GUIDANCE v3.1'!$A$3 > 1, OFFSET(BBSI!$A$3,0,0,'GUIDANCE v3.1'!$A$3,1), OFFSET(BBSI!$A$3,0,0,3,1))
Name AA.: IF('GUIDANCE v3.1'!$AA$3 > 1, OFFSET(BBSI!$AA$3,0,0,'GUIDANCE v3.1'!$AA$3,1), OFFSET(BBSI!$AA$3,0,0,3,1))
Name AB.: IF('GUIDANCE v3.1'!$AB$3 > 1, OFFSET(BBSI!$AB$3,0,0,'GUIDANCE v3.1'!$AB$3,1), OFFSET(BBSI!$AB$3,0,0,3,1))
Name AC.: IF('GUIDANCE v3.1'!$AC$3 > 1, OFFSET(BBSI!$AC$3,0,0,'GUIDANCE v3.1'!$AC$3,1), OFFSET(BBSI!$AC$3,0,0,3,1))
Name AD.: IF('GUIDANCE v3.1'!$AD$3 > 1, OFFSET(BBSI!$AD$3,0,0,'GUIDANCE v3.1'!$AD$3,1), OFFSET(BBSI!$AD$3,0,0,3,1))
Name AE.: IF('GUIDANCE v3.1'!$AE$3 > 1, OFFSET(BBSI!$AE$3,0,0,'GUIDANCE v3.1'!$AE$3,1), OFFSET(BBSI!$AE$3,0,0,3,1))
Name B.: IF('GUIDANCE v3.1'!$B$3 > 1, OFFSET(BBSI!$B$3,0,0,'GUIDANCE v3.1'!$B$3,1), OFFSET(BBSI!$B$3,0,0,3,1))
Name C.: IF('GUIDANCE v3.1'!$C$3 > 1, OFFSET(BBSI!$C$3,0,0,'GUIDANCE v3.1'!$C$3,1), OFFSET(BBSI!$C$3,0,0,3,1))
Name D.: IF('GUIDANCE v3.1'!$D$3 > 1, OFFSET(BBSI!$D$3,0,0,'GUIDANCE v3.1'!$D$3,1), OFFSET(BBSI!$D$3,0,0,3,1))
Name E.: IF('GUIDANCE v3.1'!$E$3 > 1, OFFSET(BBSI!$E$3,0,0,'GUIDANCE v3.1'!$E$3,1), OFFSET(BBSI!$E$3,0,0,3,1))
Name F.: IF('GUIDANCE v3.1'!$F$3 > 1, OFFSET(BBSI!$F$3,0,0,'GUIDANCE v3.1'!$F$3,1), OFFSET(BBSI!$F$3,0,0,3,1))
Name G.: IF('GUIDANCE v3.1'!$G$3 > 1, OFFSET(BBSI!$G$3,0,0,'GUIDANCE v3.1'!$G$3,1), OFFSET(BBSI!$G$3,0,0,3,1))
Name H.: IF('GUIDANCE v3.1'!$H$3 > 1, OFFSET(BBSI!$H$3,0,0,'GUIDANCE v3.1'!$H$3,1), OFFSET(BBSI!$H$3,0,0,3,1))
Name I.: IF('GUIDANCE v3.1'!$I$3 > 1, OFFSET(BBSI!$I$3,0,0,'GUIDANCE v3.1'!$I$3,1), OFFSET(BBSI!$I$3,0,0,3,1))
Name J.: IF('GUIDANCE v3.1'!$J$3 > 1, OFFSET(BBSI!$J$3,0,0,'GUIDANCE v3.1'!$J$3,1), OFFSET(BBSI!$J$3,0,0,3,1))
Name K.: IF('GUIDANCE v3.1'!$K$3 > 1, OFFSET(BBSI!$K$3,0,0,'GUIDANCE v3.1'!$K$3,1), OFFSET(BBSI!$K$3,0,0,3,1))
Name L.: IF('GUIDANCE v3.1'!$L$3 > 1, OFFSET(BBSI!$L$3,0,0,'GUIDANCE v3.1'!$L$3,1), OFFSET(BBSI!$L$3,0,0,3,1))
Name M.: IF('GUIDANCE v3.1'!$M$3 > 1, OFFSET(BBSI!$M$3,0,0,'GUIDANCE v3.1'!$M$3,1), OFFSET(BBSI!$M$3,0,0,3,1))
Name N.: IF('GUIDANCE v3.1'!$N$3 > 1, OFFSET(BBSI!$N$3,0,0,'GUIDANCE v3.1'!$N$3,1), OFFSET(BBSI!$N$3,0,0,3,1))
Name O.: IF('GUIDANCE v3.1'!$O$3 > 1, OFFSET(BBSI!$O$3,0,0,'GUIDANCE v3.1'!$O$3,1), OFFSET(BBSI!$O$3,0,0,3,1))
Name P.: IF('GUIDANCE v3.1'!$P$3 > 1, OFFSET(BBSI!$P$3,0,0,'GUIDANCE v3.1'!$P$3,1), OFFSET(BBSI!$P$3,0,0,3,1))
Name Q.: IF('GUIDANCE v3.1'!$Q$3 > 1, OFFSET(BBSI!$Q$3,0,0,'GUIDANCE v3.1'!$Q$3,1), OFFSET(BBSI!$Q$3,0,0,3,1))
Name R.: IF('GUIDANCE v3.1'!$R$3 > 1, OFFSET(BBSI!$R$3,0,0,'GUIDANCE v3.1'!$R$3,1), OFFSET(BBSI!$R$3,0,0,3,1))
Name S.: IF('GUIDANCE v3.1'!$S$3 > 1, OFFSET(BBSI!$S$3,0,0,'GUIDANCE v3.1'!$S$3,1), OFFSET(BBSI!$S$3,0,0,3,1))
Name T.: IF('GUIDANCE v3.1'!$T$3 > 1, OFFSET(BBSI!$T$3,0,0,'GUIDANCE v3.1'!$T$3,1), OFFSET(BBSI!$T$3,0,0,3,1))
Name U.: IF('GUIDANCE v3.1'!$U$3 > 1, OFFSET(BBSI!$U$3,0,0,'GUIDANCE v3.1'!$U$3,1), OFFSET(BBSI!$U$3,0,0,3,1))
Name V.: IF('GUIDANCE v3.1'!$V$3 > 1, OFFSET(BBSI!$V$3,0,0,'GUIDANCE v3.1'!$V$3,1), OFFSET(BBSI!$V$3,0,0,3,1))
Name W.: IF('GUIDANCE v3.1'!$W$3 > 1, OFFSET(BBSI!$W$3,0,0,'GUIDANCE v3.1'!$W$3,1), OFFSET(BBSI!$W$3,0,0,3,1))
Name X.: IF('GUIDANCE v3.1'!$X$3 > 1, OFFSET(BBSI!$X$3,0,0,'GUIDANCE v3.1'!$X$3,1), OFFSET(BBSI!$X$3,0,0,3,1))
Name Y.: IF('GUIDANCE v3.1'!$Y$3 > 1, OFFSET(BBSI!$Y$3,0,0,'GUIDANCE v3.1'!$Y$3,1), OFFSET(BBSI!$Y$3,0,0,3,1))
Name Z.: IF('GUIDANCE v3.1'!$Z$3 > 1, OFFSET(BBSI!$Z$3,0,0,'GUIDANCE v3.1'!$Z$3,1), OFFSET(BBSI!$Z$3,0,0,3,1))

Sheet BBSI
A1: {="Total Errors: "&SUM(IF(ISBLANK(A.),0,IF((LEN(A.)<>8)+(ISERROR(SEARCH(LEFT(A.),"AB")))+1-(ISNUMBER(VALUE(MID(A.,2,1))))+1-(ISNUMBER(VALUE(MID(A.,3,1))))+1-(ISNUMBER(VALUE(MID(A.,4,1))))+1-(ISNUMBER(VALUE(MID(A.,5,1))))+(MID(A.,6,1)<>"/")+1-(ISNUMBER(VALUE(MID(A.,7,1))))+1-(ISNUMBER(VALUE(MID(A.,8,1))))+ 1-(ISERROR(SEARCH("~~", A.)))+ 1-(ISERROR(SEARCH("~?", A.)))+ 1-(ISERROR(SEARCH("~*", A.))),1,0)))&CHAR(10)&"1st Error: Row "&SMALL(IF(ISBLANK(A.),FALSE,IF((SIGN(LEN(A.)<>8)+(ISERROR(SEARCH(LEFT(A.),"AB")))+1-(ISNUMBER(VALUE(MID(A.,2,1))))+1-(ISNUMBER(VALUE(MID(A.,3,1))))+1-(ISNUMBER(VALUE(MID(A.,4,1))))+1-(ISNUMBER(VALUE(MID(A.,5,1))))+(MID(A.,6,1)<>"/")+1-(ISNUMBER(VALUE(MID(A.,7,1))))+1-(ISNUMBER(VALUE(MID(A.,8,1))))+ 1-(ISERROR(SEARCH("~~", A.)))+ 1-(ISERROR(SEARCH("~?", A.)))+ 1-(ISERROR(SEARCH("~*", A.)))),ROW(A.),FALSE)),1)} -> #NUM! | B1: {="Total Errors: " & SUM(IF(ISBLANK(B.),0,IF((LEN(B.)<>1)+(ISERROR(SEARCH(LEFT(B.),"N")))+ (1-(ISERROR(SEARCH("~~", B.))))+ (1-(ISERROR(SEARCH("~?", B.))))+ (1-(ISERROR(SEARCH("~*", B.)))),1,0))) & CHAR(10) & "1st Error: Row " & SMALL(IF(ISBLANK(B.),FALSE, IF((SIGN(LEN(B.)<>1)+(ISERROR(SEARCH(LEFT(B.),"N")))+ (1-(ISERROR(SEARCH("~~", B.))))+ (1-(ISERROR(SEARCH("~?", B.))))+ (1-(ISERROR(SEARCH("~*", B.))))),ROW(B.),FALSE)),1)} -> #NUM! | C1: {="Total Errors: "&SUM(IF(ISBLANK(C.),0,IF((LEN(C.)<>4)+(ISERROR(SEARCH(LEFT(C.,2),"20")))+1-(ISNUMBER(VALUE(MID(C.,3,1))))+1-(ISNUMBER(VALUE(MID(C.,4,1))))+ 1-(ISERROR(SEARCH("~~", C.)))+ 1-(ISERROR(SEARCH("~?", C.)))+ 1-(ISERROR(SEARCH("~*", C.))),1,0)))&CHAR(10)&"1st Error: Row "&SMALL(IF(ISBLANK(C.),FALSE,IF((SIGN(LEN(C.)<>4)+(ISERROR(SEARCH(LEFT(C.,2),"20")))+1-(ISNUMBER(VALUE(MID(C.,3,1))))+1-(ISNUMBER(VALUE(MID(C.,4,1))))+ 1-(ISERROR(SEARCH("~~", C.)))+ 1-(ISERROR(SEARCH("~?", C.)))+ 1-(ISERROR(SEARCH("~*", C.)))),ROW(C.),FALSE)),1)} -> #NUM! | D1: {="Total Errors: "&SUM(IF(ISBLANK(D.),0, IF((LEN(D.)<>6)+(ISERROR(SEARCH(LEFT(D.),"0123456789")))+(ISERROR(SEARCH(MID(D.,2,1),"0123456789")))+(ISERROR(SEARCH(MID(D.,3,1),"0123456789")))+(ISERROR(SEARCH(MID(D.,4,1),"0123456789")))+(ISERROR(SEARCH(MID(D.,5,1),"0123456789")))+(ISERROR(SEARCH(RIGHT(D.),"0123456789")))+ (1-(ISERROR(SEARCH("~~", D.))))+ (1-(ISERROR(SEARCH("~?", D.))))+ (1-(ISERROR(SEARCH("~*", D.)))),1,0)))&CHAR(10)&"1st Error: Row "&SMALL(IF(ISBLANK(D.),FALSE,IF((SIGN(LEN(D.)<>6)+(ISERROR(SEARCH(LEFT(D.),"0123456789")))+(ISERROR(SEARCH(MID(D.,2,1),"0123456789")))+(ISERROR(SEARCH(MID(D.,3,1),"0123456789")))+(ISERROR(SEARCH(MID(D.,4,1),"0123456789")))+(ISERROR(SEARCH(MID(D.,5,1),"0123456789")))+(ISERROR(SEARCH(RIGHT(D.),"0123456789")))+ (1-(ISERROR(SEARCH("~~", D.))))+ (1-(ISERROR(SEARCH("~?", D.))))+ (1-(ISERROR(SEARCH("~*", D.))))),ROW(D.),FALSE)),1)} -> #NUM! | E1: {="Total Errors: " & SUM(IF(ISBLANK(E.),0,IF((LEN(E.)<>0),1,0))) & CHAR(10) & "1st Error: Row " & SMALL(IF(ISBLANK(E.),FALSE, IF((SIGN(LEN(E.)<>0)),ROW(E.),FALSE)),1)} -> #NUM! | F1: {="Total Errors: "&SUM(IF(ISBLANK(F.),0,IF((LEN(F.)>19)+ (TRIM(F.)="SEE ABOVE") + (TRIM(F.)="SEE LINE ABOVE") + (TRIM(F.)="N/K") + (TRIM(F.)="U/K")+ (TRIM(F.)="NOT APPLICABLE") + (TRIM(F.)="N/A")+ (TRIM(F.)="DITTO") + (TRIM(F.)="NOT KNOWN") + (TRIM(F.)="UNKNOWN"),1,0))) & CHAR(10) & "1st Error: Row "&SMALL(IF(ISBLANK(F.),FALSE, IF((SIGN(LEN(F.)>19)+ (TRIM(F.)="SEE ABOVE") + (TRIM(F.)="SEE LINE ABOVE") + (TRIM(F.)="N/K") + (TRIM(F.)="U/K")+ (TRIM(F.)="NOT APPLICABLE") + (TRIM(F.)="N/A")+ (TRIM(F.)="DITTO") + (TRIM(F.)="NOT KNOWN") + (TRIM(F.)="UNKNOWN")),ROW(F.),FALSE)),1)} -> #NUM! | G1: {="Total Errors: "&SUM(IF(ISBLANK(G.),0, IF((LEN(G.)>50) + (TRIM(G.)="SEE ABOVE") + (TRIM(G.)="SEE LINE ABOVE") + (TRIM(G.)="N/K") + (TRIM(G.)="U/K")+ (TRIM(G.)="NOT APPLICABLE") + (TRIM(G.)="N/A") + (TRIM(G.)="DITTO") + (TRIM(G.)="NOT KNOWN") + (TRIM(G.)="UNKNOWN"),1,0))) & CHAR(10) & "1st Error: Row " & SMALL(IF(ISBLANK(G.),FALSE,IF((SIGN(LEN(G.)>50) + (TRIM(G.)="SEE ABOVE") + (TRIM(G.)="SEE LINE ABOVE") + (TRIM(G.)="N/K") + (TRIM(G.)="U/K")+ (TRIM(G.)="NOT APPLICABLE") + (TRIM(G.)="N/A") + (TRIM(G.)="DITTO") + (TRIM(G.)="NOT KNOWN") + (TRIM(G.)="UNKNOWN")),ROW(G.),FALSE)),1)} -> #NUM! | H1: {="Total Errors: "&SUM(IF(ISBLANK(H.),0, IF((LEN(H.)>50) + (TRIM(H.)="SEE ABOVE") + (TRIM(H.)="SEE LINE ABOVE") + (TRIM(H.)="N/K") + (TRIM(H.)="U/K")+ (TRIM(H.)="NOT APPLICABLE") + (TRIM(H.)="N/A") + (TRIM(H.)="DITTO") + (TRIM(H.)="NOT KNOWN") + (TRIM(H.)="UNKNOWN"),1,0))) & CHAR(10) & "1st Error: Row " & SMALL(IF(ISBLANK(H.),FALSE,IF((SIGN(LEN(H.)>50) + (TRIM(H.)="SEE ABOVE") + (TRIM(H.)="SEE LINE ABOVE") + (TRIM(H.)="N/K") + (TRIM(H.)="U/K")+ (TRIM(H.)="NOT APPLICABLE") + (TRIM(H.)="N/A") + (TRIM(H.)="DITTO") + (TRIM(H.)="NOT KNOWN") + (TRIM(H.)="UNKNOWN")),ROW(H.),FALSE)),1)} -> #NUM! | I1: {="Total Errors: " & SUM(IF(ISBLANK(I.),0,IF((LEN(I.)<>1)+(ISERROR(SEARCH(LEFT(I.),"YN")))+ (1-(ISERROR(SEARCH("~~", I.))))+ (1-(ISERROR(SEARCH("~?", I.))))+ (1-(ISERROR(SEARCH("~*", I.)))),1,0))) & CHAR(10) & "1st Error: Row " & SMALL(IF(ISBLANK(I.),FALSE, IF((SIGN(LEN(I.)<>1)+(ISERROR(SEARCH(LEFT(I.),"YN")))+ (1-(ISERROR(SEARCH("~~", I.))))+ (1-(ISERROR(SEARCH("~?", I.))))+ (1-(ISERROR(SEARCH("~*", I.))))),ROW(I.),FALSE)),1)} -> #NUM! | J1: {="Total Errors: "&SUM(IF(ISBLANK(J.),0, IF((LEN(J.)>4)+(ISERROR(SEARCH(LEFT(J.),"0123456789")))+(ISERROR(SEARCH(MID(J.,2,1)," 0123456789")))+(ISERROR(SEARCH(MID(J.,3,1)," 0123456789")))+(ISERROR(SEARCH(RIGHT(J.)," 0123456789")))+ (1-(ISERROR(SEARCH("~~", J.))))+ (1-(ISERROR(SEARCH("~?", J.))))+ (1-(ISERROR(SEARCH("~*", J.)))),1,0)))&CHAR(10)&"1st Error: Row "&SMALL(IF(ISBLANK(J.),FALSE,IF((SIGN(LEN(J.)>4)+(ISERROR(SEARCH(LEFT(J.),"0123456789")))+(ISERROR(SEARCH(MID(J.,2,1)," 0123456789")))+(ISERROR(SEARCH(MID(J.,3,1)," 0123456789")))+(ISERROR(SEARCH(RIGHT(J.)," 0123456789")))+ (1-(ISERROR(SEARCH("~~", J.))))+ (1-(ISERROR(SEARCH("~?", J.))))+ (1-(ISERROR(SEARCH("~*", J.))))),ROW(J.),FALSE)),1)} -> #NUM! | K1: {="Total Errors: "&SUM(IF(ISBLANK(K.),0, IF((LEN(K.)>2)+(ISERROR(SEARCH(LEFT(K.),"0123456789")))+(ISERROR(SEARCH(RIGHT(K.)," 0123456789")))+ (1-(ISERROR(SEARCH("~~", K.))))+ (1-(ISERROR(SEARCH("~?", K.))))+ (1-(ISERROR(SEARCH("~*", K.)))),1,0)))&CHAR(10)&"1st Error: Row "&SMALL(IF(ISBLANK(K.),FALSE,IF((SIGN(LEN(K.)>2)+(ISERROR(SEARCH(LEFT(K.),"0123456789")))+(ISERROR(SEARCH(RIGHT(K.)," 0123456789")))+ (1-(ISERROR(SEARCH("~~", K.))))+ (1-(ISERROR(SEARCH("~?", K.))))+ (1-(ISERROR(SEARCH("~*", K.))))),ROW(K.),FALSE)),1)} -> #NUM! | L1: {="Total Errors: "&SUM(IF(ISBLANK(L.),0, IF((LEN(L.)>2)+(ISERROR(SEARCH(LEFT(L.),"0123456789")))+(ISERROR(SEARCH(RIGHT(L.)," 0123456789")))+ (1-(ISERROR(SEARCH("~~", L.))))+ (1-(ISERROR(SEARCH("~?", L.))))+ (1-(ISERROR(SEARCH("~*", L.)))),1,0)))&CHAR(10)&"1st Error: Row "&SMALL(IF(ISBLANK(L.),FALSE,IF((SIGN(LEN(L.)>2)+(ISERROR(SEARCH(LEFT(L.),"0123456789")))+(ISERROR(SEARCH(RIGHT(L.)," 0123456789")))+ (1-(ISERROR(SEARCH("~~", L.))))+ (1-(ISERROR(SEARCH("~?", L.))))+ (1-(ISERROR(SEARCH("~*", L.))))),ROW(L.),FALSE)),1)} -> #NUM! | M1: {="Total Errors: "&SUM(IF(ISBLANK(M.),0,IF((LEN(M.)>40)+(1-(ISERROR(SEARCH(CHAR(10),M.))))+(1-(ISERROR(SEARCH(CHAR(13),M.))))+(1-(ISERROR(SEARCH("@",M.))))+(1-(ISERROR(SEARCH("C/O",LEFT(M.,3)))))+(TRIM(M.)="GONE AWAY")+(TRIM(M.)="N/A")+(TRIM(M.)="NOT APPLICABLE")+(TRIM(M.)="SEE ABOVE")+(TRIM(M.)="SEE LINE ABOVE")+(TRIM(M.)="N/K")+(TRIM(M.)="DITTO")+(TRIM(M.)="NOT KNOWN")+(TRIM(M.)="UNKNOWN"),1,0)))&CHAR(10)&"1st Error: Row "&SMALL(IF(ISBLANK(M.),FALSE,IF((SIGN(LEN(M.)>40)+(1-(ISERROR(SEARCH(CHAR(10),M.))))+(1-(ISERROR(SEARCH(CHAR(13),M.))))+(1-(ISERROR(SEARCH("@",M.))))+(1-(ISERROR(SEARCH("C/O",LEFT(M.,3)))))+(TRIM(M.)="GONE AWAY")+(TRIM(M.)="N/A")+(TRIM(M.)="NOT APPLICABLE")+(TRIM(M.)="SEE ABOVE")+(TRIM(M.)="SEE LINE ABOVE")+(TRIM(M.)="N/K")+(TRIM(M.)="DITTO")+(TRIM(M.)="NOT KNOWN")+(TRIM(M.)="UNKNOWN")),ROW(M.),FALSE)),1)} -> #NUM! | N1: {="Total Errors: "&SUM(IF(ISBLANK(N.),0,IF((LEN(N.)>40)+(1-(ISERROR(SEARCH(CHAR(10),N.))))+(1-(ISERROR(SEARCH(CHAR(13),N.))))+(1-(ISERROR(SEARCH("@",N.))))+(1-(ISERROR(SEARCH("C/O",LEFT(N.,3)))))+(TRIM(N.)="GONE AWAY")+(TRIM(N.)="N/A")+(TRIM(N.)="NOT APPLICABLE")+(TRIM(N.)="SEE ABOVE")+(TRIM(N.)="SEE LINE ABOVE")+(TRIM(N.)="N/K")+(TRIM(N.)="DITTO")+(TRIM(N.)="NOT KNOWN")+(TRIM(N.)="UNKNOWN"),1,0)))&CHAR(10)&"1st Error: Row "&SMALL(IF(ISBLANK(N.),FALSE,IF((SIGN(LEN(N.)>40)+(1-(ISERROR(SEARCH(CHAR(10),N.))))+(1-(ISERROR(SEARCH(CHAR(13),N.))))+(1-(ISERROR(SEARCH("@",N.))))+(1-(ISERROR(SEARCH("C/O",LEFT(N.,3)))))+(TRIM(N.)="GONE AWAY")+(TRIM(N.)="N/A")+(TRIM(N.)="NOT APPLICABLE")+(TRIM(N.)="SEE ABOVE")+(TRIM(N.)="SEE LINE ABOVE")+(TRIM(N.)="N/K")+(TRIM(N.)="DITTO")+(TRIM(N.)="NOT KNOWN")+(TRIM(N.)="UNKNOWN")),ROW(N.),FALSE)),1)} -> #NUM! | O1: {="Total Errors: "&SUM(IF(ISBLANK(O.),0,IF((LEN(O.)>40)+(1-(ISERROR(SEARCH(CHAR(10),O.))))+(1-(ISERROR(SEARCH(CHAR(13),O.))))+(1-(ISERROR(SEARCH("@",O.))))+(1-(ISERROR(SEARCH("C/O",LEFT(O.,3)))))+(TRIM(O.)="GONE AWAY")+(TRIM(O.)="N/A")+(TRIM(O.)="NOT APPLICABLE")+(TRIM(O.)="SEE ABOVE")+(TRIM(O.)="SEE LINE ABOVE")+(TRIM(O.)="N/K")+(TRIM(O.)="DITTO")+(TRIM(O.)="NOT KNOWN")+(TRIM(O.)="UNKNOWN"),1,0)))&CHAR(10)&"1st Error: Row "&SMALL(IF(ISBLANK(O.),FALSE,IF((SIGN(LEN(O.)>40)+(1-(ISERROR(SEARCH(CHAR(10),O.))))+(1-(ISERROR(SEARCH(CHAR(13),O.))))+(1-(ISERROR(SEARCH("@",O.))))+(1-(ISERROR(SEARCH("C/O",LEFT(O.,3)))))+(TRIM(O.)="GONE AWAY")+(TRIM(O.)="N/A")+(TRIM(O.)="NOT APPLICABLE")+(TRIM(O.)="SEE ABOVE")+(TRIM(O.)="SEE LINE ABOVE")+(TRIM(O.)="N/K")+(TRIM(O.)="DITTO")+(TRIM(O.)="NOT KNOWN")+(TRIM(O.)="UNKNOWN")),ROW(O.),FALSE)),1)} -> #NUM! | P1: {="Total Errors: "&SUM(IF(ISBLANK(P.),0,IF((LEN(P.)>40)+(1-(ISERROR(SEARCH(CHAR(10),P.))))+(1-(ISERROR(SEARCH(CHAR(13),P.))))+(1-(ISERROR(SEARCH("@",P.))))+(1-(ISERROR(SEARCH("C/O",LEFT(P.,3)))))+(TRIM(P.)="GONE AWAY")+(TRIM(P.)="N/A")+(TRIM(P.)="NOT APPLICABLE")+(TRIM(P.)="SEE ABOVE")+(TRIM(P.)="SEE LINE ABOVE")+(TRIM(P.)="N/K")+(TRIM(P.)="DITTO")+(TRIM(P.)="NOT KNOWN")+(TRIM(P.)="UNKNOWN"),1,0)))&CHAR(10)&"1st Error: Row "&SMALL(IF(ISBLANK(P.),FALSE,IF((SIGN(LEN(P.)>40)+(1-(ISERROR(SEARCH(CHAR(10),P.))))+(1-(ISERROR(SEARCH(CHAR(13),P.))))+(1-(ISERROR(SEARCH("@",P.))))+(1-(ISERROR(SEARCH("C/O",LEFT(P.,3)))))+(TRIM(P.)="GONE AWAY")+(TRIM(P.)="N/A")+(TRIM(P.)="NOT APPLICABLE")+(TRIM(P.)="SEE ABOVE")+(TRIM(P.)="SEE LINE ABOVE")+(TRIM(P.)="N/K")+(TRIM(P.)="DITTO")+(TRIM(P.)="NOT KNOWN")+(TRIM(P.)="UNKNOWN")),ROW(P.),FALSE)),1)} -> #NUM! | Q1: {="Total Errors: "&SUM(IF(ISBLANK(Q.),0,IF((LEN(Q.)>40)+(1-(ISERROR(SEARCH(CHAR(10),Q.))))+(1-(ISERROR(SEARCH(CHAR(13),Q.))))+(1-(ISERROR(SEARCH("@",Q.))))+(1-(ISERROR(SEARCH("C/O",LEFT(Q.,3)))))+(TRIM(Q.)="GONE AWAY")+(TRIM(Q.)="N/A")+(TRIM(Q.)="NOT APPLICABLE")+(TRIM(Q.)="SEE ABOVE")+(TRIM(Q.)="SEE LINE ABOVE")+(TRIM(Q.)="N/K")+(TRIM(Q.)="DITTO")+(TRIM(Q.)="NOT KNOWN")+(TRIM(Q.)="UNKNOWN"),1,0)))&CHAR(10)&"1st Error: Row "&SMALL(IF(ISBLANK(Q.),FALSE,IF((SIGN(LEN(Q.)>40)+(1-(ISERROR(SEARCH(CHAR(10),Q.))))+(1-(ISERROR(SEARCH(CHAR(13),Q.))))+(1-(ISERROR(SEARCH("@",Q.))))+(1-(ISERROR(SEARCH("C/O",LEFT(Q.,3)))))+(TRIM(Q.)="GONE AWAY")+(TRIM(Q.)="N/A")+(TRIM(Q.)="NOT APPLICABLE")+(TRIM(Q.)="SEE ABOVE")+(TRIM(Q.)="SEE LINE ABOVE")+(TRIM(Q.)="N/K")+(TRIM(Q.)="DITTO")+(TRIM(Q.)="NOT KNOWN")+(TRIM(Q.)="UNKNOWN")),ROW(Q.),FALSE)),1)} -> #NUM! | R1: {="Total Errors: "&SUM(IF(ISBLANK(R.),0, IF((LEN(R.)>9)+(ISERROR(SEARCH(LEFT(R.),"abcdefghijklmnopqrstuvwxyz")))+(ISERROR(SEARCH(RIGHT(R.),"abcdefghijklmnopqrstuvwxyz")))+((ISERROR(SEARCH("0",R.)))*(ISERROR(SEARCH("1",R.)))*(ISERROR(SEARCH("2",R.)))*(ISERROR(SEARCH("3",R.)))*(ISERROR(SEARCH("4",R.)))*(ISERROR(SEARCH("5",R.)))*(ISERROR(SEARCH("6",R.)))*(ISERROR(SEARCH("7",R.)))*(ISERROR(SEARCH("8",R.)))*(ISERROR(SEARCH("9",R.))))+ (1-(ISERROR(SEARCH("~~", R.))))+(1-(ISERROR(SEARCH("~*",R.))))+(1-(ISERROR(SEARCH("~?",R.)))),1,0)))&CHAR(10)&"1st Error: Row "&SMALL(IF(ISBLANK(R.),FALSE,IF((SIGN(LEN(R.)>9)+(ISERROR(SEARCH(LEFT(R.),"abcdefghijklmnopqrstuvwxyz")))+(ISERROR(SEARCH(RIGHT(R.),"abcdefghijklmnopqrstuvwxyz")))+((ISERROR(SEARCH("0",R.)))*(ISERROR(SEARCH("1",R.)))*(ISERROR(SEARCH("2",R.)))*(ISERROR(SEARCH("3",R.)))*(ISERROR(SEARCH("4",R.)))*(ISERROR(SEARCH("5",R.)))*(ISERROR(SEARCH("6",R.)))*(ISERROR(SEARCH("7",R.)))*(ISERROR(SEARCH("8",R.)))*(ISERROR(SEARCH("9",R.))))+ (1-(ISERROR(SEARCH("~~", R.))))+(1-(ISERROR(SEARCH("~*",R.))))+(1-(ISERROR(SEARCH("~?",R.))))),ROW(R.),FALSE)),1)} -> #NUM! | S1: {="Total Errors: " & SUM((IF(ISBLANK(S.),0,IF((LEN(S.)<>2)+(ISERROR(SEARCH(LEFT(S.),"z")))+(ISERROR(SEARCH(RIGHT(S.),"z")))+ 1-(ISERROR(SEARCH("~~", S.)))+ 1-(ISERROR(SEARCH("~?", S.)))+ 1-(ISERROR(SEARCH("~*", S.))),1,0)))) & CHAR(10) & "1st Error: Row " & SMALL(IF(ISBLANK(S.),FALSE,IF((SIGN(LEN(S.)<>2)+(ISERROR(SEARCH(LEFT(S.),"z")))+(ISERROR(SEARCH(RIGHT(S.),"z")))+ 1-(ISERROR(SEARCH("~~", S.)))+ 1-(ISERROR(SEARCH("~?", S.)))+ 1-(ISERROR(SEARCH("~*", S.)))),ROW(S.),FALSE)),1)} -> #NUM! | T1: {="Total Errors: "&SUM((IF(ISBLANK(T.),0,IF((LEN(T.)<8)+(LEN(T.)>9)+(ISERROR(SEARCH(LEFT(T.),"abceghjklmnoprstwxyz")))+(ISERROR(SEARCH(MID(T.,2,1),"abceghjklmnprstwxyz")))+(1-(ISNUMBER(VALUE(MID(T.,3,1)))))+(1-(ISNUMBER(VALUE(MID(T.,4,1)))))+(1-(ISNUMBER(VALUE(MID(T.,5,1)))))+(1-(ISNUMBER(VALUE(MID(T.,6,1)))))+(1-(ISNUMBER(VALUE(MID(T.,7,1)))))+(1-(ISNUMBER(VALUE(MID(T.,8,1)))))+(ISERROR(SEARCH(MID(T.,9,1),"abcd ")))+(1-(ISERROR(SEARCH("BG",LEFT(T.,2)))))+(1-(ISERROR(SEARCH("GB",LEFT(T.,2)))))+(1-(ISERROR(SEARCH("KN",LEFT(T.,2)))))+(1-(ISERROR(SEARCH("NK",LEFT(T.,2)))))+(1-(ISERROR(SEARCH("NT",LEFT(T.,2)))))+(1-(ISERROR(SEARCH("TN",LEFT(T.,2)))))+(1-(ISERROR(SEARCH("ZZ",LEFT(T.,2))))) + (1-(ISERROR(SEARCH("~~", T.))))+ (1-(ISERROR(SEARCH("~*", T.))))+ (1-(ISERROR(SEARCH("~?", T.)))),1,0))))&CHAR(10)&"1st Error: Row "&SMALL(IF(ISBLANK(T.),FALSE,IF((SIGN(LEN(T.)<8)+(LEN(T.)>9)+(ISERROR(SEARCH(LEFT(T.),"abceghjklmnoprstwxyz")))+(ISERROR(SEARCH(MID(T.,2,1),"abceghjklmnprstwxyz")))+(1-(ISNUMBER(VALUE(MID(T.,3,1)))))+(1-(ISNUMBER(VALUE(MID(T.,4,1)))))+(1-(ISNUMBER(VALUE(MID(T.,5,1)))))+(1-(ISNUMBER(VALUE(MID(T.,6,1)))))+(1-(ISNUMBER(VALUE(MID(T.,7,1)))))+(1-(ISNUMBER(VALUE(MID(T.,8,1)))))+(ISERROR(SEARCH(MID(T.,9,1),"abcd ")))+(1-(ISERROR(SEARCH("BG",LEFT(T.,2)))))+(1-(ISERROR(SEARCH("GB",LEFT(T.,2)))))+(1-(ISERROR(SEARCH("KN",LEFT(T.,2)))))+(1-(ISERROR(SEARCH("NK",LEFT(T.,2)))))+(1-(ISERROR(SEARCH("NT",LEFT(T.,2)))))+(1-(ISERROR(SEARCH("TN",LEFT(T.,2)))))+(1-(ISERROR(SEARCH("ZZ",LEFT(T.,2)))))+ (1-(ISERROR(SEARCH("~~", T.))))+ (1-(ISERROR(SEARCH("~*", T.))))+ (1-(ISERROR(SEARCH("~?", T.))))),ROW(T.),FALSE)),1)} -> #NUM! | U1: {="Total Errors: "&SUM(IF(ISBLANK(U.),0, IF((LEN(U.)<>8)+(ISERROR(SEARCH(LEFT(U.),"0123")))+(ISERROR(SEARCH(MID(U.,2,1),"0123456789")))+(ISERROR(SEARCH(MID(U.,3,1),"01")))+(ISERROR(SEARCH(MID(U.,4,1),"0123456789")))+(ISERROR(SEARCH(MID(U.,5,1),"12")))+(ISERROR(SEARCH(MID(U.,6,1),"0123456789")))+(ISERROR(SEARCH(MID(U.,7,1),"0123456789")))+(ISERROR(SEARCH(RIGHT(U.),"0123456789")))+ (1-(ISERROR(SEARCH("~~", U.))))+ (1-(ISERROR(SEARCH("~?", U.))))+ (1-(ISERROR(SEARCH("~*", U.)))),1,0)))&CHAR(10)&"1st Error: Row "&SMALL(IF(ISBLANK(U.),FALSE,IF((SIGN(LEN(U.)<>8)+(ISERROR(SEARCH(LEFT(U.),"0123")))+(ISERROR(SEARCH(MID(U.,2,1),"0123456789")))+(ISERROR(SEARCH(MID(U.,3,1),"01")))+(ISERROR(SEARCH(MID(U.,4,1),"0123456789")))+(ISERROR(SEARCH(MID(U.,5,1),"12")))+(ISERROR(SEARCH(MID(U.,6,1),"0123456789")))+(ISERROR(SEARCH(MID(U.,7,1),"0123456789")))+(ISERROR(SEARCH(RIGHT(U.),"0123456789")))+ (1-(ISERROR(SEARCH("~~", U.))))+ (1-(ISERROR(SEARCH("~?", U.))))+ (1-(ISERROR(SEARCH("~*", U.))))),ROW(U.),FALSE)),1)} -> #NUM! | V1: {="Total Errors: "&SUM(IF(ISBLANK(V.),0,IF((LEN(V.)<>0),1,0))) & CHAR(10) & "1st Error: Row "&SMALL(IF(ISBLANK(V.),FALSE, IF((SIGN(LEN(V.)<>0)),ROW(V.),FALSE)),1)} -> #NUM! | W1: {="Total Errors: "&SUM(IF(ISBLANK(W.),0,IF((LEN(W.)<>0),1,0))) & CHAR(10) & "1st Error: Row "&SMALL(IF(ISBLANK(W.),FALSE, IF((SIGN(LEN(W.)<>0)),ROW(W.),FALSE)),1)} -> #NUM! | X1: {="Total Errors: "&SUM(IF(ISBLANK(X.),0,IF((LEN(X.)<>0),1,0))) & CHAR(10) & "1st Error: Row "&SMALL(IF(ISBLANK(X.),FALSE, IF((SIGN(LEN(X.)<>0)),ROW(X.),FALSE)),1)} -> #NUM! | Y1: {="Total Errors: "&SUM(IF(ISBLANK(Y.),0,IF((ISNUMBER(Y.)*((Y.)>999999999999.99))+(ISTEXT(Y.)*(LEN(Y.)>11))+(ISTEXT(Y.)*(ISERROR(SEARCH(".", Y.))))+(ISERROR(SEARCH(LEFT(Y.),"0123456789")))+(ISERROR(SEARCH(RIGHT(Y.),"0123456789")))+(1-(ISNUMBER(VALUE(Y.))))+(TRIM(Y.)="0")+(TRIM(Y.)="0.0")+(TRIM(Y.)="0.00")+ (1-(ISERROR(SEARCH(" ", Y.))))+ (1-(ISERROR(SEARCH(",", Y.))))+ (1-(ISERROR(SEARCH("~~", Y.))))+ (1-(ISERROR(SEARCH("~?", Y.))))+ (1-(ISERROR(SEARCH("~*", Y.)))),1,0)))&CHAR(10)&"1st Error: Row "&SMALL(IF(ISBLANK(Y.),FALSE,IF((SIGN(ISNUMBER(Y.)*((Y.)>999999999999.99))+(ISTEXT(Y.)*(LEN(Y.)>11))+(ISTEXT(Y.)*(ISERROR(SEARCH(".", Y.))))+(ISERROR(SEARCH(LEFT(Y.),"0123456789")))+(ISERROR(SEARCH(RIGHT(Y.),"0123456789")))+(1-(ISNUMBER(VALUE(Y.))))+(TRIM(Y.)="0")+(TRIM(Y.)="0.0")+(TRIM(Y.)="0.00")+ (1-(ISERROR(SEARCH(" ", Y.))))+ (1-(ISERROR(SEARCH(",", Y.))))+ (1-(ISERROR(SEARCH("~~", Y.))))+ (1-(ISERROR(SEARCH("~?", Y.))))+ (1-(ISERROR(SEARCH("~*", Y.))))),ROW(Y.),FALSE)),1)} -> #NUM! | Z1: {="Total Errors: "&SUM(IF(ISBLANK(Z.),0,IF((ISNUMBER(Z.)*((Z.)>999999999999.99))+(ISTEXT(Z.)*(LEN(Z.)>11))+(ISTEXT(Z.)*(ISERROR(SEARCH(".", Z.))))+(ISERROR(SEARCH(LEFT(Z.),"0123456789")))+(ISERROR(SEARCH(RIGHT(Z.),"0123456789")))+(1-(ISNUMBER(VALUE(Z.))))+ (1-(ISERROR(SEARCH(" ", Z.))))+ (1-(ISERROR(SEARCH(",", Z.))))+ (1-(ISERROR(SEARCH("~~", Z.))))+ (1-(ISERROR(SEARCH("~?", Z.))))+ (1-(ISERROR(SEARCH("~*", Z.)))),1,0)))&CHAR(10)&"1st Error: Row "&SMALL(IF(ISBLANK(Z.),FALSE,IF((SIGN(ISNUMBER(Z.)*((Z.)>999999999999.99))+(ISTEXT(Z.)*(LEN(Z.)>11))+(ISTEXT(Z.)*(ISERROR(SEARCH(".", Z.))))+(ISERROR(SEARCH(LEFT(Z.),"0123456789")))+(ISERROR(SEARCH(RIGHT(Z.),"0123456789")))+(1-(ISNUMBER(VALUE(Z.))))+ (1-(ISERROR(SEARCH(" ", Z.))))+ (1-(ISERROR(SEARCH(",", Z.))))+ (1-(ISERROR(SEARCH("~~", Z.))))+ (1-(ISERROR(SEARCH("~?", Z.))))+ (1-(ISERROR(SEARCH("~*", Z.))))),ROW(Z.),FALSE)),1)} -> #NUM! | AA1: {="Total Errors: " & SUM(IF(ISBLANK(AA.),0,IF((LEN(AA.)<>3)+(ISERROR(SEARCH(LEFT(AA.),"abcdefghijklmnopqrstuvwxyz")))+ISERROR(SEARCH(MID(AA.,2,1),"abcdefghijklmnopqrstuvwxyz"))+ISERROR(SEARCH(MID(AA.,3,1),"abcdefghijklmnopqrstuvwxyz"))+1-(ISERROR(SEARCH("GBR",AA.)))+1-(ISERROR(SEARCH("GPB",AA.)))+1-(ISERROR(SEARCH("GDP",AA.)))+ 1-(ISERROR(SEARCH("~~", AA.)))+ 1-(ISERROR(SEARCH("~?", AA.)))+ 1-(ISERROR(SEARCH("~*", AA.))),1,0))) & CHAR(10) & "1st Error: Row " & SMALL(IF(ISBLANK(AA.),FALSE, IF((SIGN(LEN(AA.)<>3)+(ISERROR(SEARCH(LEFT(AA.),"abcdefghijklmnopqrstuvwxyz")))+ISERROR(SEARCH(MID(AA.,2,1),"abcdefghijklmnopqrstuvwxyz"))+ISERROR(SEARCH(MID(AA.,3,1),"abcdefghijklmnopqrstuvwxyz"))+1-(ISERROR(SEARCH("GBR",AA.)))+1-(ISERROR(SEARCH("GPB",AA.)))+1-(ISERROR(SEARCH("GDP",AA.)))+ 1-(ISERROR(SEARCH("~~", AA.)))+ 1-(ISERROR(SEARCH("~?", AA.)))+ 1-(ISERROR(SEARCH("~*", AA.)))),ROW(AA.),FALSE)),1)} -> #NUM! | AB1: {="Total Errors: " & SUM(IF(ISBLANK(AB.),0,IF((LEN(AB.)<>1)+(ISERROR(SEARCH(LEFT(AB.),"YN")))+ (1-(ISERROR(SEARCH("~~", AB.))))+ (1-(ISERROR(SEARCH("~?", AB.))))+ (1-(ISERROR(SEARCH("~*", AB.)))),1,0))) & CHAR(10) & "1st Error: Row " & SMALL(IF(ISBLANK(AB.),FALSE, IF((SIGN(LEN(AB.)<>1)+(ISERROR(SEARCH(LEFT(AB.),"YN")))+ (1-(ISERROR(SEARCH("~~", AB.))))+ (1-(ISERROR(SEARCH("~?", AB.))))+ (1-(ISERROR(SEARCH("~*", AB.))))),ROW(AB.),FALSE)),1)} -> #NUM! | AC1: {="Total Errors: " & SUM(IF(ISBLANK(AC.),0,IF((LEN(AC.)<>1)+(ISERROR(SEARCH(LEFT(AC.),"N")))+ (1-(ISERROR(SEARCH("~~", AC.))))+ (1-(ISERROR(SEARCH("~?", AC.))))+ (1-(ISERROR(SEARCH("~*", AC.)))),1,0))) & CHAR(10) & "1st Error: Row " & SMALL(IF(ISBLANK(AC.),FALSE, IF((SIGN(LEN(AC.)<>1)+(ISERROR(SEARCH(LEFT(AC.),"N")))+ (1-(ISERROR(SEARCH("~~", AC.))))+ (1-(ISERROR(SEARCH("~?", AC.))))+ (1-(ISERROR(SEARCH("~*", AC.))))),ROW(AC.),FALSE)),1)} -> #NUM! | AD1: {="Total Errors: " & SUM(IF(ISBLANK(AD.),0,IF((LEN(AD.)<>1)+(ISERROR(SEARCH(LEFT(AD.),"YN")))+ (1-(ISERROR(SEARCH("~~", AD.))))+ (1-(ISERROR(SEARCH("~?", AD.))))+ (1-(ISERROR(SEARCH("~*", AD.)))),1,0))) & CHAR(10) & "1st Error: Row " & SMALL(IF(ISBLANK(AD.),FALSE, IF((SIGN(LEN(AD.)<>1)+(ISERROR(SEARCH(LEFT(AD.),"YN")))+ (1-(ISERROR(SEARCH("~~", AD.))))+ (1-(ISERROR(SEARCH("~?", AD.))))+ (1-(ISERROR(SEARCH("~*", AD.))))),ROW(AD.),FALSE)),1)} -> #NUM! | AE1: {="Total Errors: " & SUM(IF(ISBLANK(AE.),0,IF((LEN(AE.)<>1)+(ISERROR(SEARCH(LEFT(AE.),"YN")))+ (1-(ISERROR(SEARCH("~~", AE.))))+ (1-(ISERROR(SEARCH("~?", AE.))))+ (1-(ISERROR(SEARCH("~*", AE.)))),1,0))) & CHAR(10) & "1st Error: Row " & SMALL(IF(ISBLANK(AE.),FALSE, IF((SIGN(LEN(AE.)<>1)+(ISERROR(SEARCH(LEFT(AE.),"YN")))+ (1-(ISERROR(SEARCH("~~", AE.))))+ (1-(ISERROR(SEARCH("~?", AE.))))+ (1-(ISERROR(SEARCH("~*", AE.))))),ROW(AE.),FALSE)),1)} -> #NUM!
A2: Financial institution reference Mandatory field Enter your full reference (including sub reference) in row 3. Format must be: ANNNN/NN e.g. A0000/01 or B0000/01 | B2: SI 03/3297 report Mandatory field Insert N for every reported participant. | C2: Tax year Mandatory field Enter the latter year of the reported tax period in row 3. Format must be: YYYY e.g. 2022 for the 2021 to 2022 tax period. | D2: Sort code Optional field If not applicable, leave blank. If your return relates to multiple branches, enter the sort code for every reported participant in ascending numerical order. Format must be: NNNNNN e.g. 160011 | E2: Income code Leave blank | F2: Security/account number Mandatory field Data must not exceed 19 characters. Do not include the sort code. | G2: Account/client's name or relevant payee's name Mandatory field Enter the name used by your systems to identify the account or payment. Data must not exceed 50 characters. | H2: Reported participant's name Mandatory field Enter the full name of each reported participant. Data must not exceed 50 characters. | I2: Type of participant Mandatory field Enter Y for individuals and N for non-Individuals. | J2: Total number of participants Mandatory field Enter the total number of participants on the account. Data must not exceed 4 characters. Enter 0 for non-individuals. | K2: Reported participant number Mandatory field Enter sequential numbers to distinguish each reported participant on the account. Data must not exceed 2 characters. Enter 1 for non-individuals. | L2: Total number of reported participants Mandatory field Enter the total number of reported participants on the account. Data must not exceed 2 characters. Enter 1 for non-individuals. | M2: Reported participant's address line 1 Mandatory field Enter the first line of the address of the reported participant. Data must not exceed 40 characters. Do not include: ‘care of ‘addresses, UK postcodes, carriage returns or line breaks, punctuation marks or typographical symbols. | N2: Reported participant's address line 2 Optional field Only complete this field if there is more than one line in the address. Data must follow the same criteria as column M. | O2: Reported participant's address line 3 Optional field Only complete this field if there is more than one line in the address. Data must follow the same criteria as column M. | P2: Reported participant's address line 4 Optional field Only complete this field if there is more than one line in the address. Data must follow the same criteria as column M. | Q2: Reported participant's address line 5 Optional field Only complete this field if there is more than one line in the address. Data must follow the same criteria as column M. | R2: Reported participant's postcode Conditional field Enter a valid UK postcode. Data must not exceed 9 characters. Do not include punctuation marks or typographical symbols. | S2: Country code for country of residence Mandatory field Enter ZZ for every reported participant. | T2: National insurance number Optional field If not known or not applicable, leave blank. Format must be: AANNNNNNA or AANNNNNN e.g. QQ123456A or QQ123456 | U2: Date of birth Optional field If not known or not applicable, leave blank. Format must be: DDMMYYYY e.g. 03081966 | V2: Tax identification number Leave blank | W2: Country code for country of birth Leave blank | X2: Country of birth Leave blank | Y2: Gross interest paid Mandatory field Enter the total amount paid for the reported period before tax deductions. Do not include non-payments. Format must be: numerical characters to 2 decimal places e.g. 999.00 Data must not exceed 15 characters. | Z2: Tax deducted Mandatory field Enter the total amount deducted for the reported period. Duplicate the amount deducted for each reported participant. Format must be: numerical characters to 2 decimal places e.g. 999.00 Data must not exceed 15 characters. | AA2: Currency code Mandatory field Enter the 3 character ISO 4217 currency code that the reported payment was originally made in. | AB2: Conversion to sterling Mandatory field Enter either Y or N in row 3. Y: all accounts have been converted to Pound Sterling (GBP) when reporting. N: accounts have not been converted and payment value relates to the reported currency. | AC2: R105 signal Mandatory field Enter N | AD2: R85 gross registration Mandatory field Enter N | AE2: New account Mandatory field Enter Y if this is the first time account has been reported. Enter N if the account has been previously reported.

Sheet GUIDANCE v3.1
B1: SPREADSHEET ERROR VALIDATION HELP GUIDE version 3.1
A3: {=LOOKUP(2,1/(NOT(ISBLANK(BBSI!$A:$A))), ROW(BBSI!$A:$A)) - 2} -> 0 | B3: {=LOOKUP(2,1/(NOT(ISBLANK(BBSI!$B:$B))), ROW(BBSI!$B:$B)) - 2} -> 0 | C3: {=LOOKUP(2,1/(NOT(ISBLANK(BBSI!$C:$C))), ROW(BBSI!$C:$C)) - 2} -> 0 | D3: {=LOOKUP(2,1/(NOT(ISBLANK(BBSI!$D:$D))), ROW(BBSI!$D:$D)) - 2} -> 0 | E3: {=LOOKUP(2,1/(NOT(ISBLANK(BBSI!$E:$E))), ROW(BBSI!$E:$E)) - 2} -> 0 | F3: {=LOOKUP(2,1/(NOT(ISBLANK(BBSI!$F:$F))), ROW(BBSI!$F:$F)) - 2} -> 0 | G3: {=LOOKUP(2,1/(NOT(ISBLANK(BBSI!$G:$G))), ROW(BBSI!$G:$G)) - 2} -> 0 | H3: {=LOOKUP(2,1/(NOT(ISBLANK(BBSI!$H:$H))), ROW(BBSI!$H:$H)) - 2} -> 0 | I3: {=LOOKUP(2,1/(NOT(ISBLANK(BBSI!$I:$I))), ROW(BBSI!$I:$I)) - 2} -> 0 | J3: {=LOOKUP(2,1/(NOT(ISBLANK(BBSI!$J:$J))), ROW(BBSI!$J:$J)) - 2} -> 0 | K3: {=LOOKUP(2,1/(NOT(ISBLANK(BBSI!$K:$K))), ROW(BBSI!$K:$K)) - 2} -> 0 | L3: {=LOOKUP(2,1/(NOT(ISBLANK(BBSI!$L:$L))), ROW(BBSI!$L:$L)) - 2} -> 0 | M3: {=LOOKUP(2,1/(NOT(ISBLANK(BBSI!$M:$M))), ROW(BBSI!$M:$M)) - 2} -> 0 | N3: {=LOOKUP(2,1/(NOT(ISBLANK(BBSI!$N:$N))), ROW(BBSI!$N:$N)) - 2} -> 0 | O3: {=LOOKUP(2,1/(NOT(ISBLANK(BBSI!$O:$O))), ROW(BBSI!$O:$O)) - 2} -> 0 | P3: {=LOOKUP(2,1/(NOT(ISBLANK(BBSI!$P:$P))), ROW(BBSI!$P:$P)) - 2} -> 0 | Q3: {=LOOKUP(2,1/(NOT(ISBLANK(BBSI!$Q:$Q))), ROW(BBSI!$Q:$Q)) - 2} -> 0 | R3: {=LOOKUP(2,1/(NOT(ISBLANK(BBSI!$R:$R))), ROW(BBSI!$R:$R)) - 2} -> 0 | S3: {=LOOKUP(2,1/(NOT(ISBLANK(BBSI!$S:$S))), ROW(BBSI!$S:$S)) - 2} -> 0 | T3: {=LOOKUP(2,1/(NOT(ISBLANK(BBSI!$T:$T))), ROW(BBSI!$T:$T)) - 2} -> 0 | U3: {=LOOKUP(2,1/(NOT(ISBLANK(BBSI!$U:$U))), ROW(BBSI!$U:$U)) - 2} -> 0 | V3: {=LOOKUP(2,1/(NOT(ISBLANK(BBSI!$V:$V))), ROW(BBSI!$V:$V)) - 2} -> 0 | W3: {=LOOKUP(2,1/(NOT(ISBLANK(BBSI!$W:$W))), ROW(BBSI!$W:$W)) - 2} -> 0 | X3: {=LOOKUP(2,1/(NOT(ISBLANK(BBSI!$X:$X))), ROW(BBSI!$X:$X)) - 2} -> 0 | Y3: {=LOOKUP(2,1/(NOT(ISBLANK(BBSI!$Y:$Y))), ROW(BBSI!$Y:$Y)) - 2} -> 0 | Z3: {=LOOKUP(2,1/(NOT(ISBLANK(BBSI!$Z:$Z))), ROW(BBSI!$Z:$Z)) - 2} -> 0 | AA3: {=LOOKUP(2,1/(NOT(ISBLANK(BBSI!$AA:$AA))), ROW(BBSI!$AA:$AA)) - 2} -> 0 | AB3: {=LOOKUP(2,1/(NOT(ISBLANK(BBSI!$AB:$AB))), ROW(BBSI!$AB:$AB)) - 2} -> 0 | AC3: {=LOOKUP(2,1/(NOT(ISBLANK(BBSI!$AC:$AC))), ROW(BBSI!$AC:$AC)) - 2} -> 0 | AD3: {=LOOKUP(2,1/(NOT(ISBLANK(BBSI!$AD:$AD))), ROW(BBSI!$AD:$AD)) - 2} -> 0 | AE3: {=LOOKUP(2,1/(NOT(ISBLANK(BBSI!$AE:$AE))), ROW(BBSI!$AE:$AE)) - 2} -> 0
A4: v All mandatory fields MUST be completed using the values instructed.
A6: v You MUST complete conditional fields ONLY where the conditions stated apply.
A8: v The error validation formulas embedded within the template are a customer support tool to assist the data supplier when entering their information.
A10: v For each column, ROW 1 will turn AMBER to indicate that there is an error within the data supplied for that specific column.
A12: v Validation will also provide the error count for that specific column (total number of fields containing errors) and the 1st error row number.
A14: v Once the field containing the 1st error has been corrected, the 1st error row number will update to indicate the next field error within that column (if applicable).
A16: v After all errors within a specific column have been corrected, row 1 for that column will cease to be amber, indicating that there are no further recognised errors within that column.
A18: v Please note when entering information that the error validation has been designed as a customer support tool and is NOT able to identify all potential errors which would be identified in subsequent HMRC data processing.
A20: v Therefore please also refer to the guidance on ROW 1 of the template for further information on the requirements for supplying your data.
A22: v Please DON'T change any data entry field formats or the original file format as this may affect the error validation.
A24: v If you are pasting your data onto the spreadsheet please ensure that you use the paste special option and select values to ensure that the original data entry field format is not overwritten.
A26: v Please be aware that due to the size and complexity of the error validation formulas, you may experience delays with the validation response when inputting & correcting data.
... A36: v Please see below the specific error validations for each individual data type/column.
B38: Data Error Validations (Columns A - AE)
B40: COLUMN A
B41: Financial Institution Reference
B43: WHAT DOES IT VALIDATE
B44: · Data supplied MATCHES 8 character specific length.
B45: · Data supplied BEGINS with either A or B.
B46: · Data supplied MATCHES required format ANNNN/NN.
B47: · NO other characters are acceptable.
B48: · Data supplied does NOT contain blank spaces.
B51: COLUMN B
B52: SI 03/3297 Report
B54: WHAT DOES IT VALIDATE
... B93: · Data supplied is NOT one of the following unacceptable data entries:
B95: SEE ABOVE | C95: SEE LINE ABOVE | D95: N/K | E95: N/A | F95: U/K
B96: DITTO | C96: NOT KNOWN | D96: UNKNOWN | E96: NOT APPLICABLE
B99: COLUMN G
B100: Account/Client's Name or Relevant Payee's/Residual Entity's Name
B102: WHAT DOES IT VALIDATE
B103: · Data supplied does NOT exceed maximum 50 character length.
B104: · Data supplied is NOT one of the following unacceptable data entries:
B106: SEE ABOVE | C106: SEE LINE ABOVE | D106: N/K | E106: N/A | F106: U/K
B107: DITTO | C107: NOT KNOWN | D107: UNKNOWN | E107: NOT APPLICABLE
B110: COLUMN H
B111: Reported Participant's Name
B113: WHAT DOES IT VALIDATE
...
