Workbook
Name A.: IF('GUIDANCE v2.5'!$A$6 > 1, OFFSET(ISA!$A$3,0,0,'GUIDANCE v2.5'!$A$6,1), OFFSET(ISA!$A$3,0,0,3,1))
Name AA.: IF('GUIDANCE v2.5'!$AA$6 > 1, OFFSET(ISA!$AA$3,0,0,'GUIDANCE v2.5'!$AA$6,1), OFFSET(ISA!$AA$3,0,0,3,1))
Name AB.: IF('GUIDANCE v2.5'!$AB$6 > 1, OFFSET(ISA!$AB$3,0,0,'GUIDANCE v2.5'!$AB$6,1), OFFSET(ISA!$AB$3,0,0,3,1))
Name B.: IF('GUIDANCE v2.5'!$B$6 > 1, OFFSET(ISA!$B$3,0,0,'GUIDANCE v2.5'!$B$6,1), OFFSET(ISA!$B$3,0,0,3,1))
Name C.: IF('GUIDANCE v2.5'!$C$6 > 1, OFFSET(ISA!$C$3,0,0,'GUIDANCE v2.5'!$C$6,1), OFFSET(ISA!$C$3,0,0,3,1))
Name D.: IF('GUIDANCE v2.5'!$D$6 > 1, OFFSET(ISA!$D$3,0,0,'GUIDANCE v2.5'!$D$6,1), OFFSET(ISA!$D$3,0,0,3,1))
Name E.: IF('GUIDANCE v2.5'!$E$6 > 1, OFFSET(ISA!$E$3,0,0,'GUIDANCE v2.5'!$E$6,1), OFFSET(ISA!$E$3,0,0,3,1))
Name F.: IF('GUIDANCE v2.5'!$F$6 > 1, OFFSET(ISA!$F$3,0,0,'GUIDANCE v2.5'!$F$6,1), OFFSET(ISA!$F$3,0,0,3,1))
Name G.: IF('GUIDANCE v2.5'!$G$6 > 1, OFFSET(ISA!$G$3,0,0,'GUIDANCE v2.5'!$G$6,1), OFFSET(ISA!$G$3,0,0,3,1))
Name H.: IF('GUIDANCE v2.5'!$H$6 > 1, OFFSET(ISA!$H$3,0,0,'GUIDANCE v2.5'!$H$6,1), OFFSET(ISA!$H$3,0,0,3,1))
Name I.: IF('GUIDANCE v2.5'!$I$6 > 1, OFFSET(ISA!$I$3,0,0,'GUIDANCE v2.5'!$I$6,1), OFFSET(ISA!$I$3,0,0,3,1))
Name J.: IF('GUIDANCE v2.5'!$J$6 > 1, OFFSET(ISA!$J$3,0,0,'GUIDANCE v2.5'!$J$6,1), OFFSET(ISA!$J$3,0,0,3,1))
Name K.: IF('GUIDANCE v2.5'!$K$6 > 1, OFFSET(ISA!$K$3,0,0,'GUIDANCE v2.5'!$K$6,1), OFFSET(ISA!$K$3,0,0,3,1))
Name L.: IF('GUIDANCE v2.5'!$L$6 > 1, OFFSET(ISA!$L$3,0,0,'GUIDANCE v2.5'!$L$6,1), OFFSET(ISA!$L$3,0,0,3,1))
Name M.: IF('GUIDANCE v2.5'!$M$6 > 1, OFFSET(ISA!$M$3,0,0,'GUIDANCE v2.5'!$M$6,1), OFFSET(ISA!$M$3,0,0,3,1))
Name N.: IF('GUIDANCE v2.5'!$N$6 > 1, OFFSET(ISA!$N$3,0,0,'GUIDANCE v2.5'!$N$6,1), OFFSET(ISA!$N$3,0,0,3,1))
Name O.: IF('GUIDANCE v2.5'!$O$6 > 1, OFFSET(ISA!$O$3,0,0,'GUIDANCE v2.5'!$O$6,1), OFFSET(ISA!$O$3,0,0,3,1))
Name P.: IF('GUIDANCE v2.5'!$P$6 > 1, OFFSET(ISA!$P$3,0,0,'GUIDANCE v2.5'!$P$6,1), OFFSET(ISA!$P$3,0,0,3,1))
Name Q.: IF('GUIDANCE v2.5'!$Q$6 > 1, OFFSET(ISA!$Q$3,0,0,'GUIDANCE v2.5'!$Q$6,1), OFFSET(ISA!$Q$3,0,0,3,1))
Name R.: IF('GUIDANCE v2.5'!$R$6 > 1, OFFSET(ISA!$R$3,0,0,'GUIDANCE v2.5'!$R$6,1), OFFSET(ISA!$R$3,0,0,3,1))
Name S.: IF('GUIDANCE v2.5'!$S$6 > 1, OFFSET(ISA!$S$3,0,0,'GUIDANCE v2.5'!$S$6,1), OFFSET(ISA!$S$3,0,0,3,1))
Name T.: IF('GUIDANCE v2.5'!$T$6 > 1, OFFSET(ISA!$T$3,0,0,'GUIDANCE v2.5'!$T$6,1), OFFSET(ISA!$T$3,0,0,3,1))
Name U.: IF('GUIDANCE v2.5'!$U$6 > 1, OFFSET(ISA!$U$3,0,0,'GUIDANCE v2.5'!$U$6,1), OFFSET(ISA!$U$3,0,0,3,1))
Name V.: IF('GUIDANCE v2.5'!$V$6 > 1, OFFSET(ISA!$V$3,0,0,'GUIDANCE v2.5'!$V$6,1), OFFSET(ISA!$V$3,0,0,3,1))
Name W.: IF('GUIDANCE v2.5'!$W$6 > 1, OFFSET(ISA!$W$3,0,0,'GUIDANCE v2.5'!$W$6,1), OFFSET(ISA!$W$3,0,0,3,1))
Name X.: IF('GUIDANCE v2.5'!$X$6 > 1, OFFSET(ISA!$X$3,0,0,'GUIDANCE v2.5'!$X$6,1), OFFSET(ISA!$X$3,0,0,3,1))
Name Y.: IF('GUIDANCE v2.5'!$Y$6 > 1, OFFSET(ISA!$Y$3,0,0,'GUIDANCE v2.5'!$Y$6,1), OFFSET(ISA!$Y$3,0,0,3,1))
Name Z.: IF('GUIDANCE v2.5'!$Z$6 > 1, OFFSET(ISA!$Z$3,0,0,'GUIDANCE v2.5'!$Z$6,1), OFFSET(ISA!$Z$3,0,0,3,1))

Sheet ISA
A1: {="Error Count: "&SUM(IF(ISBLANK(A.),0,IF((LEN(A.)<>8)+(ISERROR(SEARCH(LEFT(A.),"Z")))+(1-(ISNUMBER(VALUE(MID(A.,2,1)))))+(1-(ISNUMBER(VALUE(MID(A.,3,1)))))+(1-(ISNUMBER(VALUE(MID(A.,4,1)))))+(1-(ISNUMBER(VALUE(MID(A.,5,1)))))+(MID(A.,6,1)<>"/")+(1-(ISNUMBER(VALUE(MID(A.,7,1)))))+(1-(ISNUMBER(VALUE(MID(A.,8,1)))))+ (1-(ISERROR(SEARCH("~~", A.))))+ (1-(ISERROR(SEARCH("~?", A.))))+ (1-(ISERROR(SEARCH("~*", A.)))),1,0)))&CHAR(10)&"1st Error Row: "&SMALL(IF(ISBLANK(A.),FALSE,IF((SIGN(LEN(A.)<>8)+(ISERROR(SEARCH(LEFT(A.),"Z")))+(1-(ISNUMBER(VALUE(MID(A.,2,1)))))+(1-(ISNUMBER(VALUE(MID(A.,3,1)))))+(1-(ISNUMBER(VALUE(MID(A.,4,1)))))+(1-(ISNUMBER(VALUE(MID(A.,5,1)))))+(MID(A.,6,1)<>"/")+(1-(ISNUMBER(VALUE(MID(A.,7,1)))))+(1-(ISNUMBER(VALUE(MID(A.,8,1)))))+ (1-(ISERROR(SEARCH("~~", A.))))+ (1-(ISERROR(SEARCH("~?", A.))))+ (1-(ISERROR(SEARCH("~*", A.))))),ROW(A.),FALSE)),1)} -> #NUM! | B1: {="Error Count: "&SUM(IF(ISBLANK(B.),0, IF((LEN(B.)>50) + (TRIM(B.)="SEE ABOVE") + (TRIM(B.)="SEE LINE ABOVE") + (TRIM(B.)="N/K") + (TRIM(B.)="U/K")+ (TRIM(B.)="NOT APPLICABLE") + (TRIM(B.)="N/A") + (TRIM(B.)="DITTO") + (TRIM(B.)="NOT KNOWN") + (TRIM(B.)="UNKNOWN"),1,0))) & CHAR(10) & "1st Error Row: " & SMALL(IF(ISBLANK(B.),FALSE,IF((SIGN(LEN(B.)>50) + (TRIM(B.)="SEE ABOVE") + (TRIM(B.)="SEE LINE ABOVE") + (TRIM(B.)="N/K") + (TRIM(B.)="U/K")+ (TRIM(B.)="NOT APPLICABLE") + (TRIM(B.)="N/A") + (TRIM(B.)="DITTO") + (TRIM(B.)="NOT KNOWN") + (TRIM(B.)="UNKNOWN")),ROW(B.),FALSE)),1)} -> #NUM! | C1: {="Error Count: "&SUM(IF(ISBLANK(C.),0,IF((LEN(C.)<>4)+(ISERROR(SEARCH(LEFT(C.,2),"20")))+(1-(ISNUMBER(VALUE(MID(C.,3,1)))))+(1-(ISNUMBER(VALUE(MID(C.,4,1)))))+ (1-(ISERROR(SEARCH("~~", C.))))+ (1-(ISERROR(SEARCH("~?", C.))))+ (1-(ISERROR(SEARCH("~*", C.)))),1,0)))&CHAR(10)&"1st Error Row: "&SMALL(IF(ISBLANK(C.),FALSE,IF((SIGN(LEN(C.)<>4)+(ISERROR(SEARCH(LEFT(C.,2),"20")))+(1-(ISNUMBER(VALUE(MID(C.,3,1)))))+(1-(ISNUMBER(VALUE(MID(C.,4,1)))))+ (1-(ISERROR(SEARCH("~~", C.))))+ (1-(ISERROR(SEARCH("~?", C.))))+ (1-(ISERROR(SEARCH("~*", C.))))),ROW(C.),FALSE)),1)} -> #NUM! | D1: {="Error Count: "&SUM(IF(ISBLANK(D.),0,IF((LEN(D.)>20)+ (TRIM(D.)="SEE ABOVE") + (TRIM(D.)="SEE LINE ABOVE") + (TRIM(D.)="N/K") + (TRIM(D.)="U/K")+ (TRIM(D.)="NOT APPLICABLE") + (TRIM(D.)="N/A")+ (TRIM(D.)="DITTO") + (TRIM(D.)="NOT KNOWN") + (TRIM(D.)="UNKNOWN"),1,0))) & CHAR(10) & "1st Error Row: "&SMALL(IF(ISBLANK(D.),FALSE, IF((SIGN(LEN(D.)>19)+ (TRIM(D.)="SEE ABOVE") + (TRIM(D.)="SEE LINE ABOVE") + (TRIM(D.)="N/K") + (TRIM(D.)="U/K")+ (TRIM(D.)="NOT APPLICABLE") + (TRIM(D.)="N/A")+ (TRIM(D.)="DITTO") + (TRIM(D.)="NOT KNOWN") + (TRIM(D.)="UNKNOWN")),ROW(D.),FALSE)),1)} -> #NUM! | E1: {="Error Count: " & SUM(IF(ISBLANK(E.),0,IF((LEN(E.)<>1)+(ISERROR(SEARCH(LEFT(E.),"ABCDEFGHSTXYZ")))+ (1-(ISERROR(SEARCH("~~", E.))))+ (1-(ISERROR(SEARCH("~?", E.))))+ (1-(ISERROR(SEARCH("~*", E.)))),1,0))) & CHAR(10) & "1st Error Row: " & SMALL(IF(ISBLANK(E.),FALSE, IF((SIGN(LEN(E.)<>1)+(ISERROR(SEARCH(LEFT(E.),"ABCDEFGHSTXYZ")))+ (1-(ISERROR(SEARCH("~~", E.))))+ (1-(ISERROR(SEARCH("~?", E.))))+ (1-(ISERROR(SEARCH("~*", E.))))),ROW(E.),FALSE)),1)} -> #NUM! | F1: {="Error Count: "&SUM(IF(ISBLANK(F.),0, IF((LEN(F.)>10) + (TRIM(F.)="SEE ABOVE") + (TRIM(F.)="SEE LINE ABOVE") + (TRIM(F.)="N/K") + (TRIM(F.)="U/K")+ (TRIM(F.)="NOT APPLICABLE") + (TRIM(F.)="N/A")+ (TRIM(F.)="DITTO") + (TRIM(F.)="NOT KNOWN") + (TRIM(F.)="UNKNOWN"),1,0))) & CHAR(10) & "1st Error Row: " & SMALL(IF(ISBLANK(F.),FALSE,IF((SIGN(LEN(F.)>10) + (TRIM(F.)="SEE ABOVE") + (TRIM(F.)="SEE LINE ABOVE") + (TRIM(F.)="N/K") + (TRIM(F.)="U/K")+ (TRIM(F.)="NOT APPLICABLE") + (TRIM(F.)="N/A")+ (TRIM(F.)="DITTO") + (TRIM(F.)="NOT KNOWN") + (TRIM(F.)="UNKNOWN")),ROW(F.),FALSE)),1)} -> #NUM! | G1: {="Error Count: "&SUM(IF(ISBLANK(G.),0, IF((LEN(G.)>50) + (TRIM(G.)="SEE ABOVE") + (TRIM(G.)="SEE LINE ABOVE") + (TRIM(G.)="N/K") + (TRIM(G.)="U/K")+ (TRIM(G.)="NOT APPLICABLE") + (TRIM(G.)="N/A")+ (TRIM(G.)="DITTO") + (TRIM(G.)="NOT KNOWN") + (TRIM(G.)="UNKNOWN"),1,0))) & CHAR(10) & "1st Error Row: " & SMALL(IF(ISBLANK(G.),FALSE,IF((SIGN(LEN(G.)>50) + (TRIM(G.)="SEE ABOVE") + (TRIM(G.)="SEE LINE ABOVE") + (TRIM(G.)="N/K") + (TRIM(G.)="U/K")+ (TRIM(G.)="NOT APPLICABLE") + (TRIM(G.)="N/A")+ (TRIM(G.)="DITTO") + (TRIM(G.)="NOT KNOWN") + (TRIM(G.)="UNKNOWN")),ROW(G.),FALSE)),1)} -> #NUM! | H1: {="Error Count: "&SUM(IF(ISBLANK(H.),0, IF((LEN(H.)>50) + (TRIM(H.)="SEE ABOVE") + (TRIM(H.)="SEE LINE ABOVE") + (TRIM(H.)="N/K") + (TRIM(H.)="U/K")+ (TRIM(H.)="NOT APPLICABLE") + (TRIM(H.)="N/A")+ (TRIM(H.)="DITTO") + (TRIM(H.)="NOT KNOWN") + (TRIM(H.)="UNKNOWN"),1,0))) & CHAR(10) & "1st Error Row: " & SMALL(IF(ISBLANK(H.),FALSE,IF((SIGN(LEN(H.)>50) + (TRIM(H.)="SEE ABOVE") + (TRIM(H.)="SEE LINE ABOVE") + (TRIM(H.)="N/K") + (TRIM(H.)="U/K")+ (TRIM(H.)="NOT APPLICABLE") + (TRIM(H.)="N/A")+ (TRIM(H.)="DITTO") + (TRIM(H.)="NOT KNOWN") + (TRIM(H.)="UNKNOWN")),ROW(H.),FALSE)),1)} -> #NUM! | I1: {="Error Count: "&SUM(IF(ISBLANK(I.),0, IF((LEN(I.)<>8)+(ISERROR(SEARCH(LEFT(I.),"0123")))+(ISERROR(SEARCH(MID(I.,2,1),"0123456789")))+(ISERROR(SEARCH(MID(I.,3,1),"01")))+(ISERROR(SEARCH(MID(I.,4,1),"0123456789")))+(ISERROR(SEARCH(MID(I.,5,1),"12")))+(ISERROR(SEARCH(MID(I.,6,1),"0123456789")))+(ISERROR(SEARCH(MID(I.,7,1),"0123456789")))+(ISERROR(SEARCH(RIGHT(I.),"0123456789")))+ (1-(ISERROR(SEARCH("~~", I.))))+ (1-(ISERROR(SEARCH("~?", I.))))+ (1-(ISERROR(SEARCH("~*", I.)))),1,0)))&CHAR(10)&"1st Error Row: "&SMALL(IF(ISBLANK(I.),FALSE,IF((SIGN(LEN(I.)<>8)+(ISERROR(SEARCH(LEFT(I.),"0123")))+(ISERROR(SEARCH(MID(I.,2,1),"0123456789")))+(ISERROR(SEARCH(MID(I.,3,1),"01")))+(ISERROR(SEARCH(MID(I.,4,1),"0123456789")))+(ISERROR(SEARCH(MID(I.,5,1),"12")))+(ISERROR(SEARCH(MID(I.,6,1),"0123456789")))+(ISERROR(SEARCH(MID(I.,7,1),"0123456789")))+(ISERROR(SEARCH(RIGHT(I.),"0123456789")))+ (1-(ISERROR(SEARCH("~~", I.))))+ (1-(ISERROR(SEARCH("~?", I.))))+ (1-(ISERROR(SEARCH("~*", I.))))),ROW(I.),FALSE)),1)} -> #NUM! | J1: {="Error Count: "&SUM((IF(ISBLANK(J.),0,IF((LEN(J.)<8)+(LEN(J.)>9)+(ISERROR(SEARCH(LEFT(J.),"abceghjklmnopqrstwxyz")))+(ISERROR(SEARCH(MID(J.,2,1),"abceghjklmnpqrstwxyz")))+(1-(ISNUMBER(VALUE(MID(J.,3,1)))))+(1-(ISNUMBER(VALUE(MID(J.,4,1)))))+(1-(ISNUMBER(VALUE(MID(J.,5,1)))))+(1-(ISNUMBER(VALUE(MID(J.,6,1)))))+(1-(ISNUMBER(VALUE(MID(J.,7,1)))))+(1-(ISNUMBER(VALUE(MID(J.,8,1)))))+(ISERROR(SEARCH(MID(J.,9,1),"abcd ")))+(1-(ISERROR(SEARCH("BG",LEFT(J.,2)))))+(1-(ISERROR(SEARCH("GB",LEFT(J.,2)))))+(1-(ISERROR(SEARCH("KN",LEFT(J.,2)))))+(1-(ISERROR(SEARCH("NK",LEFT(J.,2)))))+(1-(ISERROR(SEARCH("NT",LEFT(J.,2)))))+(1-(ISERROR(SEARCH("TN",LEFT(J.,2)))))+(1-(ISERROR(SEARCH("ZZ",LEFT(J.,2))))) + (1-(ISERROR(SEARCH("~~", J.))))+ (1-(ISERROR(SEARCH("~*", J.))))+ (1-(ISERROR(SEARCH("~?", J.)))),1,0))))&CHAR(10)&"1st Error Row: "&SMALL(IF(ISBLANK(J.),FALSE,IF((SIGN(LEN(J.)<8)+(LEN(J.)>9)+(ISERROR(SEARCH(LEFT(J.),"abceghjklmnopqrstwxyz")))+(ISERROR(SEARCH(MID(J.,2,1),"abceghjklmnpqrstwxyz")))+(1-(ISNUMBER(VALUE(MID(J.,3,1)))))+(1-(ISNUMBER(VALUE(MID(J.,4,1)))))+(1-(ISNUMBER(VALUE(MID(J.,5,1)))))+(1-(ISNUMBER(VALUE(MID(J.,6,1)))))+(1-(ISNUMBER(VALUE(MID(J.,7,1)))))+(1-(ISNUMBER(VALUE(MID(J.,8,1)))))+(ISERROR(SEARCH(MID(J.,9,1),"abcd ")))+(1-(ISERROR(SEARCH("BG",LEFT(J.,2)))))+(1-(ISERROR(SEARCH("GB",LEFT(J.,2)))))+(1-(ISERROR(SEARCH("KN",LEFT(J.,2)))))+(1-(ISERROR(SEARCH("NK",LEFT(J.,2)))))+(1-(ISERROR(SEARCH("NT",LEFT(J.,2)))))+(1-(ISERROR(SEARCH("TN",LEFT(J.,2)))))+(1-(ISERROR(SEARCH("ZZ",LEFT(J.,2)))))+ (1-(ISERROR(SEARCH("~~", J.))))+ (1-(ISERROR(SEARCH("~*", J.))))+ (1-(ISERROR(SEARCH("~?", J.))))),ROW(J.),FALSE)),1)} -> #NUM! | K1: {="Error Count: "&SUM(IF(ISBLANK(K.),0,IF((LEN(K.)>40)+(1-(ISERROR(SEARCH(CHAR(10),K.))))+(1-(ISERROR(SEARCH(CHAR(13),K.))))+(1-(ISERROR(SEARCH("@",K.))))+(1-(ISERROR(SEARCH("C/O",LEFT(K.,3)))))+(TRIM(K.)="GONE AWAY")+(TRIM(K.)="N/A")+(TRIM(K.)="NOT APPLICABLE")+(TRIM(K.)="SEE ABOVE")+(TRIM(K.)="SEE LINE ABOVE")+(TRIM(K.)="N/K")+(TRIM(K.)="DITTO")+(TRIM(K.)="NOT KNOWN")+(TRIM(K.)="UNKNOWN"),1,0)))&CHAR(10)&"1st Error Row: "&SMALL(IF(ISBLANK(K.),FALSE,IF((SIGN(LEN(K.)>40)+(1-(ISERROR(SEARCH(CHAR(10),K.))))+(1-(ISERROR(SEARCH(CHAR(13),K.))))+(1-(ISERROR(SEARCH("@",K.))))+(1-(ISERROR(SEARCH("C/O",LEFT(K.,3)))))+(TRIM(K.)="GONE AWAY")+(TRIM(K.)="N/A")+(TRIM(K.)="NOT APPLICABLE")+(TRIM(K.)="SEE ABOVE")+(TRIM(K.)="SEE LINE ABOVE")+(TRIM(K.)="N/K")+(TRIM(K.)="DITTO")+(TRIM(K.)="NOT KNOWN")+(TRIM(K.)="UNKNOWN")),ROW(K.),FALSE)),1)} -> #NUM! | L1: {="Error Count: "&SUM(IF(ISBLANK(L.),0,IF((LEN(L.)>40)+(1-(ISERROR(SEARCH(CHAR(10),L.))))+(1-(ISERROR(SEARCH(CHAR(13),L.))))+(1-(ISERROR(SEARCH("@",L.))))+(1-(ISERROR(SEARCH("C/O",LEFT(L.,3)))))+(TRIM(L.)="GONE AWAY")+(TRIM(L.)="N/A")+(TRIM(L.)="NOT APPLICABLE")+(TRIM(L.)="SEE ABOVE")+(TRIM(L.)="SEE LINE ABOVE")+(TRIM(L.)="N/K")+(TRIM(L.)="DITTO")+(TRIM(L.)="NOT KNOWN")+(TRIM(L.)="UNKNOWN"),1,0)))&CHAR(10)&"1st Error Row: "&SMALL(IF(ISBLANK(L.),FALSE,IF((SIGN(LEN(L.)>40)+(1-(ISERROR(SEARCH(CHAR(10),L.))))+(1-(ISERROR(SEARCH(CHAR(13),L.))))+(1-(ISERROR(SEARCH("@",L.))))+(1-(ISERROR(SEARCH("C/O",LEFT(L.,3)))))+(TRIM(L.)="GONE AWAY")+(TRIM(L.)="N/A")+(TRIM(L.)="NOT APPLICABLE")+(TRIM(L.)="SEE ABOVE")+(TRIM(L.)="SEE LINE ABOVE")+(TRIM(L.)="N/K")+(TRIM(L.)="DITTO")+(TRIM(L.)="NOT KNOWN")+(TRIM(L.)="UNKNOWN")),ROW(L.),FALSE)),1)} -> #NUM! | M1: {="Error Count: "&SUM(IF(ISBLANK(M.),0,IF((LEN(M.)>40)+(1-(ISERROR(SEARCH(CHAR(10),M.))))+(1-(ISERROR(SEARCH(CHAR(13),M.))))+(1-(ISERROR(SEARCH("@",M.))))+(1-(ISERROR(SEARCH("C/O",LEFT(M.,3)))))+(TRIM(M.)="GONE AWAY")+(TRIM(M.)="N/A")+(TRIM(M.)="NOT APPLICABLE")+(TRIM(M.)="SEE ABOVE")+(TRIM(M.)="SEE LINE ABOVE")+(TRIM(M.)="N/K")+(TRIM(M.)="DITTO")+(TRIM(M.)="NOT KNOWN")+(TRIM(M.)="UNKNOWN"),1,0)))&CHAR(10)&"1st Error Row: "&SMALL(IF(ISBLANK(M.),FALSE,IF((SIGN(LEN(M.)>40)+(1-(ISERROR(SEARCH(CHAR(10),M.))))+(1-(ISERROR(SEARCH(CHAR(13),M.))))+(1-(ISERROR(SEARCH("@",M.))))+(1-(ISERROR(SEARCH("C/O",LEFT(M.,3)))))+(TRIM(M.)="GONE AWAY")+(TRIM(M.)="N/A")+(TRIM(M.)="NOT APPLICABLE")+(TRIM(M.)="SEE ABOVE")+(TRIM(M.)="SEE LINE ABOVE")+(TRIM(M.)="N/K")+(TRIM(M.)="DITTO")+(TRIM(M.)="NOT KNOWN")+(TRIM(M.)="UNKNOWN")),ROW(M.),FALSE)),1)} -> #NUM! | N1: {="Error Count: "&SUM(IF(ISBLANK(N.),0,IF((LEN(N.)>40)+(1-(ISERROR(SEARCH(CHAR(10),N.))))+(1-(ISERROR(SEARCH(CHAR(13),N.))))+(1-(ISERROR(SEARCH("@",N.))))+(1-(ISERROR(SEARCH("C/O",LEFT(N.,3)))))+(TRIM(N.)="GONE AWAY")+(TRIM(N.)="N/A")+(TRIM(N.)="NOT APPLICABLE")+(TRIM(N.)="SEE ABOVE")+(TRIM(N.)="SEE LINE ABOVE")+(TRIM(N.)="N/K")+(TRIM(N.)="DITTO")+(TRIM(N.)="NOT KNOWN")+(TRIM(N.)="UNKNOWN"),1,0)))&CHAR(10)&"1st Error Row: "&SMALL(IF(ISBLANK(N.),FALSE,IF((SIGN(LEN(N.)>40)+(1-(ISERROR(SEARCH(CHAR(10),N.))))+(1-(ISERROR(SEARCH(CHAR(13),N.))))+(1-(ISERROR(SEARCH("@",N.))))+(1-(ISERROR(SEARCH("C/O",LEFT(N.,3)))))+(TRIM(N.)="GONE AWAY")+(TRIM(N.)="N/A")+(TRIM(N.)="NOT APPLICABLE")+(TRIM(N.)="SEE ABOVE")+(TRIM(N.)="SEE LINE ABOVE")+(TRIM(N.)="N/K")+(TRIM(N.)="DITTO")+(TRIM(N.)="NOT KNOWN")+(TRIM(N.)="UNKNOWN")),ROW(N.),FALSE)),1)} -> #NUM! | O1: {="Error Count: "&SUM(IF(ISBLANK(O.),0,IF((LEN(O.)>40)+(1-(ISERROR(SEARCH(CHAR(10),O.))))+(1-(ISERROR(SEARCH(CHAR(13),O.))))+(1-(ISERROR(SEARCH("@",O.))))+(1-(ISERROR(SEARCH("C/O",LEFT(O.,3)))))+(TRIM(O.)="GONE AWAY")+(TRIM(O.)="N/A")+(TRIM(O.)="NOT APPLICABLE")+(TRIM(O.)="SEE ABOVE")+(TRIM(O.)="SEE LINE ABOVE")+(TRIM(O.)="N/K")+(TRIM(O.)="DITTO")+(TRIM(O.)="NOT KNOWN")+(TRIM(O.)="UNKNOWN"),1,0)))&CHAR(10)&"1st Error Row: "&SMALL(IF(ISBLANK(O.),FALSE,IF((SIGN(LEN(O.)>40)+(1-(ISERROR(SEARCH(CHAR(10),O.))))+(1-(ISERROR(SEARCH(CHAR(13),O.))))+(1-(ISERROR(SEARCH("@",O.))))+(1-(ISERROR(SEARCH("C/O",LEFT(O.,3)))))+(TRIM(O.)="GONE AWAY")+(TRIM(O.)="N/A")+(TRIM(O.)="NOT APPLICABLE")+(TRIM(O.)="SEE ABOVE")+(TRIM(O.)="SEE LINE ABOVE")+(TRIM(O.)="N/K")+(TRIM(O.)="DITTO")+(TRIM(O.)="NOT KNOWN")+(TRIM(O.)="UNKNOWN")),ROW(O.),FALSE)),1)} -> #NUM! | P1: {="Error Count: "&SUM(IF(ISBLANK(P.),0, IF((LEN(P.)>8)+((ISERROR(SEARCH("0",P.)))*(ISERROR(SEARCH("1",P.)))*(ISERROR(SEARCH("2",P.)))*(ISERROR(SEARCH("3",P.)))*(ISERROR(SEARCH("4",P.)))*(ISERROR(SEARCH("5",P.)))*(ISERROR(SEARCH("6",P.)))*(ISERROR(SEARCH("7",P.)))*(ISERROR(SEARCH("8",P.)))*(ISERROR(SEARCH("9",P.))))+ (1-(ISERROR(SEARCH("~~", P.))))+(1-(ISERROR(SEARCH("~*",P.))))+(1-(ISERROR(SEARCH("~?",P.)))),1,0)))&CHAR(10)&"1st Error Row: "&SMALL(IF(ISBLANK(P.),FALSE,IF((SIGN(LEN(P.)>8)+((ISERROR(SEARCH("0",P.)))*(ISERROR(SEARCH("1",P.)))*(ISERROR(SEARCH("2",P.)))*(ISERROR(SEARCH("3",P.)))*(ISERROR(SEARCH("4",P.)))*(ISERROR(SEARCH("5",P.)))*(ISERROR(SEARCH("6",P.)))*(ISERROR(SEARCH("7",P.)))*(ISERROR(SEARCH("8",P.)))*(ISERROR(SEARCH("9",P.))))+ (1-(ISERROR(SEARCH("~~", P.))))+(1-(ISERROR(SEARCH("~*",P.))))+(1-(ISERROR(SEARCH("~?",P.))))),ROW(P.),FALSE)),1)} -> #NUM! | Q1: {="Error Count: "&SUM(IF(ISBLANK(Q.),0,IF((ISNUMBER(Q.)*((Q.)>99999999))+(ISTEXT(Q.)*(LEN(Q.)>8))+(ISTEXT(Q.)*(1-(ISERROR(SEARCH(".", Q.)))))+(ISERROR(SEARCH(LEFT(Q.),"0123456789")))+(ISERROR(SEARCH(RIGHT(Q.),"0123456789")))+(1-(ISNUMBER(VALUE(Q.))))+ (1-(ISERROR(SEARCH(" ", Q.))))+ (1-(ISERROR(SEARCH(",", Q.))))+ (1-(ISERROR(SEARCH("~~", Q.))))+ (1-(ISERROR(SEARCH("~?", Q.))))+ (1-(ISERROR(SEARCH("~*", Q.)))),1,0)))&CHAR(10)&"1st Error Row: "&SMALL(IF(ISBLANK(Q.),FALSE,IF((SIGN(ISNUMBER(Q.)*((Q.)>99999999))+(ISTEXT(Q.)*(LEN(Q.)>8))+(ISTEXT(Q.)*(1-(ISERROR(SEARCH(".", Q.)))))+(ISERROR(SEARCH(LEFT(Q.),"0123456789")))+(ISERROR(SEARCH(RIGHT(Q.),"0123456789")))+(1-(ISNUMBER(VALUE(Q.))))+ (1-(ISERROR(SEARCH(" ", Q.))))+ (1-(ISERROR(SEARCH(",", Q.))))+ (1-(ISERROR(SEARCH("~~", Q.))))+ (1-(ISERROR(SEARCH("~?", Q.))))+ (1-(ISERROR(SEARCH("~*", Q.))))),ROW(Q.),FALSE)),1)} -> #NUM! | R1: {="Error Count: "&SUM(IF(ISBLANK(R.),0,IF((ISNUMBER(R.)*((R.)>99999999))+(ISTEXT(R.)*(LEN(R.)>8))+(ISTEXT(R.)*(1-(ISERROR(SEARCH(".", R.)))))+(ISERROR(SEARCH(LEFT(R.),"0123456789")))+(ISERROR(SEARCH(RIGHT(R.),"0123456789")))+(1-(ISNUMBER(VALUE(R.))))+ (1-(ISERROR(SEARCH(" ", R.))))+ (1-(ISERROR(SEARCH(",", R.))))+ (1-(ISERROR(SEARCH("~~", R.))))+ (1-(ISERROR(SEARCH("~?", R.))))+ (1-(ISERROR(SEARCH("~*", R.)))),1,0)))&CHAR(10)&"1st Error Row: "&SMALL(IF(ISBLANK(R.),FALSE,IF((SIGN(ISNUMBER(R.)*((R.)>99999999))+(ISTEXT(R.)*(LEN(R.)>8))+(ISTEXT(R.)*(1-(ISERROR(SEARCH(".", R.)))))+(ISERROR(SEARCH(LEFT(R.),"0123456789")))+(ISERROR(SEARCH(RIGHT(R.),"0123456789")))+(1-(ISNUMBER(VALUE(R.))))+ (1-(ISERROR(SEARCH(" ", R.))))+ (1-(ISERROR(SEARCH(",", R.))))+ (1-(ISERROR(SEARCH("~~", R.))))+ (1-(ISERROR(SEARCH("~?", R.))))+ (1-(ISERROR(SEARCH("~*", R.))))),ROW(R.),FALSE)),1)} -> #NUM! | S1: {="Error Count: "&SUM(IF(ISBLANK(S.),0,IF((ISNUMBER(S.)*((S.)>99999999))+(ISTEXT(S.)*(LEN(S.)>8))+(ISTEXT(S.)*(1-(ISERROR(SEARCH(".", S.)))))+(ISERROR(SEARCH(LEFT(S.),"0123456789")))+(ISERROR(SEARCH(RIGHT(S.),"0123456789")))+(1-(ISNUMBER(VALUE(S.))))+ (1-(ISERROR(SEARCH(" ", S.))))+ (1-(ISERROR(SEARCH(",", S.))))+ (1-(ISERROR(SEARCH("~~", S.))))+ (1-(ISERROR(SEARCH("~?", S.))))+ (1-(ISERROR(SEARCH("~*", S.)))),1,0)))&CHAR(10)&"1st Error Row: "&SMALL(IF(ISBLANK(S.),FALSE,IF((SIGN(ISNUMBER(S.)*((S.)>99999999))+(ISTEXT(S.)*(LEN(S.)>8))+(ISTEXT(S.)*(1-(ISERROR(SEARCH(".", S.)))))+(ISERROR(SEARCH(LEFT(S.),"0123456789")))+(ISERROR(SEARCH(RIGHT(S.),"0123456789")))+(1-(ISNUMBER(VALUE(S.))))+ (1-(ISERROR(SEARCH(" ", S.))))+ (1-(ISERROR(SEARCH(",", S.))))+ (1-(ISERROR(SEARCH("~~", S.))))+ (1-(ISERROR(SEARCH("~?", S.))))+ (1-(ISERROR(SEARCH("~*", S.))))),ROW(S.),FALSE)),1)} -> #NUM! | T1: {="Error Count: "&SUM(IF(ISBLANK(T.),0,IF((ISNUMBER(T.)*((T.)>99999999))+(ISTEXT(T.)*(LEN(T.)>8))+(ISTEXT(T.)*(1-(ISERROR(SEARCH(".", T.)))))+(ISERROR(SEARCH(LEFT(T.),"0123456789")))+(ISERROR(SEARCH(RIGHT(T.),"0123456789")))+(1-(ISNUMBER(VALUE(T.))))+ (1-(ISERROR(SEARCH(" ", T.))))+ (1-(ISERROR(SEARCH(",", T.))))+ (1-(ISERROR(SEARCH("~~", T.))))+ (1-(ISERROR(SEARCH("~?", T.))))+ (1-(ISERROR(SEARCH("~*", T.)))),1,0)))&CHAR(10)&"1st Error Row: "&SMALL(IF(ISBLANK(T.),FALSE,IF((SIGN(ISNUMBER(T.)*((T.)>99999999))+(ISTEXT(T.)*(LEN(T.)>8))+(ISTEXT(T.)*(1-(ISERROR(SEARCH(".", T.)))))+(ISERROR(SEARCH(LEFT(T.),"0123456789")))+(ISERROR(SEARCH(RIGHT(T.),"0123456789")))+(1-(ISNUMBER(VALUE(T.))))+ (1-(ISERROR(SEARCH(" ", T.))))+ (1-(ISERROR(SEARCH(",", T.))))+ (1-(ISERROR(SEARCH("~~", T.))))+ (1-(ISERROR(SEARCH("~?", T.))))+ (1-(ISERROR(SEARCH("~*", T.))))),ROW(T.),FALSE)),1)} -> #NUM! | U1: {="Error Count: "&SUM(IF(ISBLANK(U.),0,IF((ISNUMBER(U.)*((U.)>99999999))+(ISTEXT(U.)*(LEN(U.)>8))+(ISTEXT(U.)*(1-(ISERROR(SEARCH(".", U.)))))+(ISERROR(SEARCH(LEFT(U.),"0123456789")))+(ISERROR(SEARCH(RIGHT(U.),"0123456789")))+(1-(ISNUMBER(VALUE(U.))))+ (1-(ISERROR(SEARCH(" ", U.))))+ (1-(ISERROR(SEARCH(",", U.))))+ (1-(ISERROR(SEARCH("~~", U.))))+ (1-(ISERROR(SEARCH("~?", U.))))+ (1-(ISERROR(SEARCH("~*", U.)))),1,0)))&CHAR(10)&"1st Error Row: "&SMALL(IF(ISBLANK(U.),FALSE,IF((SIGN(ISNUMBER(U.)*((U.)>99999999))+(ISTEXT(U.)*(LEN(U.)>8))+(ISTEXT(U.)*(1-(ISERROR(SEARCH(".", U.)))))+(ISERROR(SEARCH(LEFT(U.),"0123456789")))+(ISERROR(SEARCH(RIGHT(U.),"0123456789")))+(1-(ISNUMBER(VALUE(U.))))+ (1-(ISERROR(SEARCH(" ", U.))))+ (1-(ISERROR(SEARCH(",", U.))))+ (1-(ISERROR(SEARCH("~~", U.))))+ (1-(ISERROR(SEARCH("~?", U.))))+ (1-(ISERROR(SEARCH("~*", U.))))),ROW(U.),FALSE)),1)} -> #NUM! | V1: {="Error Count: "&SUM(IF(ISBLANK(V.),0, IF((LEN(V.)<>8)+(ISERROR(SEARCH(LEFT(V.),"0123")))+(ISERROR(SEARCH(MID(V.,2,1),"0123456789")))+(ISERROR(SEARCH(MID(V.,3,1),"01")))+(ISERROR(SEARCH(MID(V.,4,1),"0123456789")))+(ISERROR(SEARCH(MID(V.,5,1),"12")))+(ISERROR(SEARCH(MID(V.,6,1),"0123456789")))+(ISERROR(SEARCH(MID(V.,7,1),"0123456789")))+(ISERROR(SEARCH(RIGHT(V.),"0123456789")))+ (1-(ISERROR(SEARCH("~~", V.))))+ (1-(ISERROR(SEARCH("~?", V.))))+ (1-(ISERROR(SEARCH("~*", V.)))),1,0)))&CHAR(10)&"1st Error Row: "&SMALL(IF(ISBLANK(V.),FALSE,IF((SIGN(LEN(V.)<>8)+(ISERROR(SEARCH(LEFT(V.),"0123")))+(ISERROR(SEARCH(MID(V.,2,1),"0123456789")))+(ISERROR(SEARCH(MID(V.,3,1),"01")))+(ISERROR(SEARCH(MID(V.,4,1),"0123456789")))+(ISERROR(SEARCH(MID(V.,5,1),"12")))+(ISERROR(SEARCH(MID(V.,6,1),"0123456789")))+(ISERROR(SEARCH(MID(V.,7,1),"0123456789")))+(ISERROR(SEARCH(RIGHT(V.),"0123456789")))+ (1-(ISERROR(SEARCH("~~", V.))))+ (1-(ISERROR(SEARCH("~?", V.))))+ (1-(ISERROR(SEARCH("~*", V.))))),ROW(V.),FALSE)),1)} -> #NUM! | W1: {="Error Count: "&SUM(IF(ISBLANK(W.),0,IF((ISNUMBER(W.)*((W.)>99999999))+(ISTEXT(W.)*(LEN(W.)>8))+(ISTEXT(W.)*(1-(ISERROR(SEARCH(".", W.)))))+(ISERROR(SEARCH(LEFT(W.),"0123456789")))+(ISERROR(SEARCH(RIGHT(W.),"0123456789")))+(1-(ISNUMBER(VALUE(W.))))+ (1-(ISERROR(SEARCH(" ", W.))))+ (1-(ISERROR(SEARCH(",", W.))))+ (1-(ISERROR(SEARCH("~~", W.))))+ (1-(ISERROR(SEARCH("~?", W.))))+ (1-(ISERROR(SEARCH("~*", W.)))),1,0)))&CHAR(10)&"1st Error Row: "&SMALL(IF(ISBLANK(W.),FALSE,IF((SIGN(ISNUMBER(W.)*((W.)>99999999))+(ISTEXT(W.)*(LEN(W.)>8))+(ISTEXT(W.)*(1-(ISERROR(SEARCH(".", W.)))))+(ISERROR(SEARCH(LEFT(W.),"0123456789")))+(ISERROR(SEARCH(RIGHT(W.),"0123456789")))+(1-(ISNUMBER(VALUE(W.))))+ (1-(ISERROR(SEARCH(" ", W.))))+ (1-(ISERROR(SEARCH(",", W.))))+ (1-(ISERROR(SEARCH("~~", W.))))+ (1-(ISERROR(SEARCH("~?", W.))))+ (1-(ISERROR(SEARCH("~*", W.))))),ROW(W.),FALSE)),1)} -> #NUM! | X1: {="Error Count: "&SUM(IF(ISBLANK(X.),0,IF((ISNUMBER(X.)*((X.)>999999999999999))+(ISTEXT(X.)*(LEN(X.)>20))+(ISTEXT(X.)*(1-(ISERROR(SEARCH(".", X.)))))+(ISERROR(SEARCH(LEFT(X.),"0123456789")))+(ISERROR(SEARCH(RIGHT(X.),"0123456789")))+(1-(ISNUMBER(VALUE(X.))))+ (1-(ISERROR(SEARCH(" ", X.))))+ (1-(ISERROR(SEARCH(",", X.))))+ (1-(ISERROR(SEARCH("~~", X.))))+ (1-(ISERROR(SEARCH("~?", X.))))+ (1-(ISERROR(SEARCH("~*", X.)))),1,0)))&CHAR(10)&"1st Error Row: "&SMALL(IF(ISBLANK(X.),FALSE,IF((SIGN(ISNUMBER(X.)*((X.)>999999999999999))+(ISTEXT(X.)*(LEN(X.)>20))+(ISTEXT(X.)*(1-(ISERROR(SEARCH(".", X.)))))+(ISERROR(SEARCH(LEFT(X.),"0123456789")))+(ISERROR(SEARCH(RIGHT(X.),"0123456789")))+(1-(ISNUMBER(VALUE(X.))))+ (1-(ISERROR(SEARCH(" ", X.))))+ (1-(ISERROR(SEARCH(",", X.))))+ (1-(ISERROR(SEARCH("~~", X.))))+ (1-(ISERROR(SEARCH("~?", X.))))+ (1-(ISERROR(SEARCH("~*", X.))))),ROW(X.),FALSE)),1)} -> #NUM! | Y1: {="Error Count: "&SUM(IF(ISBLANK(Y.),0,IF((ISNUMBER(Y.)*((Y.)>9999999999))+(ISTEXT(Y.)*(LEN(Y.)>10))+(ISTEXT(Y.)*(1-(ISERROR(SEARCH(".", Y.)))))+(ISERROR(SEARCH(LEFT(Y.),"0123456789")))+(ISERROR(SEARCH(RIGHT(Y.),"0123456789")))+(1-(ISNUMBER(VALUE(Y.))))+ (1-(ISERROR(SEARCH(" ", Y.))))+ (1-(ISERROR(SEARCH(",", Y.))))+ (1-(ISERROR(SEARCH("~~", Y.))))+ (1-(ISERROR(SEARCH("~?", Y.))))+ (1-(ISERROR(SEARCH("~*", Y.)))),1,0)))&CHAR(10)&"1st Error Row: "&SMALL(IF(ISBLANK(Y.),FALSE,IF((SIGN(ISNUMBER(Y.)*((Y.)>9999999999))+(ISTEXT(Y.)*(LEN(Y.)>10))+(ISTEXT(Y.)*(1-(ISERROR(SEARCH(".", Y.)))))+(ISERROR(SEARCH(LEFT(Y.),"0123456789")))+(ISERROR(SEARCH(RIGHT(Y.),"0123456789")))+(1-(ISNUMBER(VALUE(Y.))))+ (1-(ISERROR(SEARCH(" ", Y.))))+ (1-(ISERROR(SEARCH(",", Y.))))+ (1-(ISERROR(SEARCH("~~", Y.))))+ (1-(ISERROR(SEARCH("~?", Y.))))+ (1-(ISERROR(SEARCH("~*", Y.))))),ROW(Y.),FALSE)),1)} -> #NUM! | Z1: {="Error Count: "&SUM(IF(ISBLANK(Z.),0,IF((ISNUMBER(Z.)*((Z.)>9999999999))+(ISTEXT(Z.)*(LEN(Z.)>10))+(ISTEXT(Z.)*(1-(ISERROR(SEARCH(".", Z.)))))+(ISERROR(SEARCH(LEFT(Z.),"0123456789")))+(ISERROR(SEARCH(RIGHT(Z.),"0123456789")))+(1-(ISNUMBER(VALUE(Z.))))+ (1-(ISERROR(SEARCH(" ", Z.))))+ (1-(ISERROR(SEARCH(",", Z.))))+ (1-(ISERROR(SEARCH("~~", Z.))))+ (1-(ISERROR(SEARCH("~?", Z.))))+ (1-(ISERROR(SEARCH("~*", Z.)))),1,0)))&CHAR(10)&"1st Error Row: "&SMALL(IF(ISBLANK(Z.),FALSE,IF((SIGN(ISNUMBER(Z.)*((Z.)>9999999999))+(ISTEXT(Z.)*(LEN(Z.)>10))+(ISTEXT(Z.)*(1-(ISERROR(SEARCH(".", Z.)))))+(ISERROR(SEARCH(LEFT(Z.),"0123456789")))+(ISERROR(SEARCH(RIGHT(Z.),"0123456789")))+(1-(ISNUMBER(VALUE(Z.))))+ (1-(ISERROR(SEARCH(" ", Z.))))+ (1-(ISERROR(SEARCH(",", Z.))))+ (1-(ISERROR(SEARCH("~~", Z.))))+ (1-(ISERROR(SEARCH("~?", Z.))))+ (1-(ISERROR(SEARCH("~*", Z.))))),ROW(Z.),FALSE)),1)} -> #NUM! | AA1: {="Error Count: "&SUM(IF(ISBLANK(AA.),0,IF((ISNUMBER(AA.)*((AA.)>999999999999999))+(ISTEXT(AA.)*(LEN(AA.)>20))+(ISTEXT(AA.)*(1-(ISERROR(SEARCH(".", AA.)))))+(ISERROR(SEARCH(LEFT(AA.),"0123456789")))+(ISERROR(SEARCH(RIGHT(AA.),"0123456789")))+(1-(ISNUMBER(VALUE(AA.))))+ (1-(ISERROR(SEARCH(" ", AA.))))+ (1-(ISERROR(SEARCH(",", AA.))))+ (1-(ISERROR(SEARCH("~~", AA.))))+ (1-(ISERROR(SEARCH("~?", AA.))))+ (1-(ISERROR(SEARCH("~*", AA.)))),1,0)))&CHAR(10)&"1st Error Row: "&SMALL(IF(ISBLANK(AA.),FALSE,IF((SIGN(ISNUMBER(AA.)*((AA.)>999999999999999))+(ISTEXT(AA.)*(LEN(AA.)>20))+(ISTEXT(AA.)*(1-(ISERROR(SEARCH(".", AA.)))))+(ISERROR(SEARCH(LEFT(AA.),"0123456789")))+(ISERROR(SEARCH(RIGHT(AA.),"0123456789")))+(1-(ISNUMBER(VALUE(AA.))))+ (1-(ISERROR(SEARCH(" ", AA.))))+ (1-(ISERROR(SEARCH(",", AA.))))+ (1-(ISERROR(SEARCH("~~", AA.))))+ (1-(ISERROR(SEARCH("~?", AA.))))+ (1-(ISERROR(SEARCH("~*", AA.))))),ROW(AA.),FALSE)),1)} -> #NUM! | AB1: {="Error Count: "&SUM(IF(ISBLANK(AB.),0, IF((LEN(AB.)<>8)+(ISERROR(SEARCH(LEFT(AB.),"0123")))+(ISERROR(SEARCH(MID(AB.,2,1),"0123456789")))+(ISERROR(SEARCH(MID(AB.,3,1),"01")))+(ISERROR(SEARCH(MID(AB.,4,1),"0123456789")))+(ISERROR(SEARCH(MID(AB.,5,1),"12")))+(ISERROR(SEARCH(MID(AB.,6,1),"0123456789")))+(ISERROR(SEARCH(MID(AB.,7,1),"0123456789")))+(ISERROR(SEARCH(RIGHT(AB.),"0123456789")))+ (1-(ISERROR(SEARCH("~~", AB.))))+ (1-(ISERROR(SEARCH("~?", AB.))))+ (1-(ISERROR(SEARCH("~*", AB.)))),1,0)))&CHAR(10)&"1st Error Row: "&SMALL(IF(ISBLANK(AB.),FALSE,IF((SIGN(LEN(AB.)<>8)+(ISERROR(SEARCH(LEFT(AB.),"0123")))+(ISERROR(SEARCH(MID(AB.,2,1),"0123456789")))+(ISERROR(SEARCH(MID(AB.,3,1),"01")))+(ISERROR(SEARCH(MID(AB.,4,1),"0123456789")))+(ISERROR(SEARCH(MID(AB.,5,1),"12")))+(ISERROR(SEARCH(MID(AB.,6,1),"0123456789")))+(ISERROR(SEARCH(MID(AB.,7,1),"0123456789")))+(ISERROR(SEARCH(RIGHT(AB.),"0123456789")))+ (1-(ISERROR(SEARCH("~~", AB.))))+ (1-(ISERROR(SEARCH("~?", AB.))))+ (1-(ISERROR(SEARCH("~*", AB.))))),ROW(AB.),FALSE)),1)} -> #NUM!
A2: {=IFERROR("ISA Manager Reference" & CHAR(10) & "8 Characters" & CHAR(10) & "MANDATORY FIELD"& CHAR(10) & "(" &SUM(IF((($A$3:$A$3)=""),1,0)) & " Not Completed)","ISA Manager Reference" & CHAR(10) & "8 Characters" & CHAR(10) & "MANDATORY FIELD")} -> ISA Manager Reference 8 Characters MANDATORY FIELD (1 Not Completed) | B2: {=IFERROR("ISA Manager's Name" & CHAR(10) & "Max. 50 Characters" & CHAR(10) & "MANDATORY FIELD"& CHAR(10) & "(" &SUM(IF((($B$3:$B$3)=""),1,0)) & " Not Completed)","ISA Manager's Name" & CHAR(10) & "Max. 50 Characters" & CHAR(10) & "MANDATORY FIELD")} -> ISA Manager's Name Max. 50 Characters MANDATORY FIELD (1 Not Completed) | C2: {=IFERROR("Tax Year" & CHAR(10) & "4 Characters" & CHAR(10) & "MANDATORY FIELD"& CHAR(10) & "(" &SUM(IF((($C$3:$C$3)=""),1,0)) & " Not Completed)","Tax Year" & CHAR(10) & "4 Characters" & CHAR(10) & "MANDATORY FIELD")} -> Tax Year 4 Characters MANDATORY FIELD (1 Not Completed) | D2: {=IFERROR("ISA/JISA Account Number" & CHAR(10) & "Max. 20 Characters" & CHAR(10) & "MANDATORY FIELD"& CHAR(10) & "(" &SUM(IF((($D$3:$D$1048576)="")*((($E$3:$E$1048576)<>"")+(($G$3:$G$1048576)<>"")),1,0)) & " Not Completed)","ISA/JISA Account Number" & CHAR(10) & "Max. 20 Characters" & CHAR(10) & "MANDATORY FIELD")} -> ISA/JISA Account Number Max. 20 Characters MANDATORY FIELD (0 Not Completed) | E2: {=IFERROR("ISA/JISA Type" & CHAR(10) & "1 Character" & CHAR(10) & "MANDATORY FIELD"& CHAR(10) & "(" &SUM(IF((($E$3:$E$1048576)="")*((($D$3:$D$1048576)<>"")+(($G$3:$G$1048576)<>"")),1,0)) & " Not Completed)","ISA/JISA Type" & CHAR(10) & "1 Character" & CHAR(10) & "MANDATORY FIELD")} -> ISA/JISA Type 1 Character MANDATORY FIELD (0 Not Completed) | F2: Investor's Title Max. 10 Characters CONDITIONAL FIELD | G2: {=IFERROR("Investor's Forename(s)" & CHAR(10) & "Max. 50 Characters" & CHAR(10) & "MANDATORY FIELD"& CHAR(10) & "(" &SUM(IF((($G$3:$G$1048576)="")*((($E$3:$E$1048576)<>"")+(($H$3:$H$1048576)<>"")),1,0)) & " Not Completed)","Investor's Forename(s)" & CHAR(10) & "Max. 50 Characters" & CHAR(10) & "MANDATORY FIELD")} -> Investor's Forename(s) Max. 50 Characters MANDATORY FIELD (0 Not Completed) | H2: {=IFERROR("Investor's Surname" & CHAR(10) & "Max. 50 Characters" & CHAR(10) & "MANDATORY FIELD"& CHAR(10) & "(" &SUM(IF((($H$3:$H$1048576)="")*((($G$3:$G$1048576)<>"")+(($K$3:$K$1048576)<>"")),1,0)) & " Not Completed)","Investor's Surname" & CHAR(10) & "Max. 50 Characters" & CHAR(10) & "MANDATORY FIELD")} -> Investor's Surname Max. 50 Characters MANDATORY FIELD (0 Not Completed) | I2: Date of Birth 8 Characters CONDITIONAL FIELD | J2: National Insurance Number (NINO) 8-9 Characters CONDITIONAL FIELD | K2: {=IFERROR("Investor's Address Line 1" & CHAR(10) & "Max. 40 Characters" & CHAR(10) & "MANDATORY FIELD"& CHAR(10) & "(" &SUM(IF((($K$3:$K$1048576)="")*((($G$3:$G$1048576)<>"")+(($H$3:$H$1048576)<>"")),1,0)) & " Not Completed)","Investor's Address Line 1" & CHAR(10) & "Max. 40 Characters" & CHAR(10) & "MANDATORY FIELD")} -> Investor's Address Line 1 Max. 40 Characters MANDATORY FIELD (0 Not Completed) | L2: Investor's Address Line 2 Max. 40 Characters CONDITIONAL FIELD | M2: Investor's Address Line 3 Max. 40 Characters CONDITIONAL FIELD | N2: Investor's Address Line 4 Max. 40 Characters CONDITIONAL FIELD | O2: Investor's Address Line 5 Max. 40 Characters CONDITIONAL FIELD | P2: Investor's Postcode Max. 8 Characters CONDITIONAL FIELD | Q2: Amount Subscribed to Stocks & Shares ISA/JISA Max. 8 Characters CONDITIONAL FIELD | R2: Amount Subscribed to Cash ISA/JISA Max. 8 Characters CONDITIONAL FIELD | S2: Amount Subscribed to Innovative Finance ISA Max. 8 Characters CONDITIONAL FIELD | T2: Amount of Subscriptions Used to Buy Insurance Max. 8 Characters CONDITIONAL FIELD | U2: Total Amount Subscribed Max. 8 Characters CONDITIONAL FIELD | V2: Date of 1st Subscription 8 Characters CONDITIONAL FIELD | W2: Share Transfer Amount (ISA ONLY) Max. 8 Characters CONDITIONAL FIELD | X2: Stocks & Shares ISA/JISA Market Value Max. 20 Characters CONDITIONAL FIELD | Y2: Cash ISA/JISA Market Value Max. 10 Characters CONDITIONAL FIELD | Z2: Innovative Finance ISA Market Value Max. 10 Characters CONDITIONAL FIELD | AA2: Insurance Market Value Max. 20 Characters CONDITIONAL FIELD | AB2: Closure Date 8 Characters CONDITIONAL FIELD

Sheet GUIDANCE v2.5
D1: SPREADSHEET TEMPLATE ERROR VALIDATION GUIDANCE version 2.5
A6: {=LOOKUP(2,1/(NOT(ISBLANK(ISA!$A:$A))), ROW(ISA!$A:$A)) - 2} -> 0 | B6: {=LOOKUP(2,1/(NOT(ISBLANK(ISA!$B:$B))), ROW(ISA!$B:$B)) - 2} -> 0 | C6: {=LOOKUP(2,1/(NOT(ISBLANK(ISA!$C:$C))), ROW(ISA!$C:$C)) - 2} -> 0 | D6: {=LOOKUP(2,1/(NOT(ISBLANK(ISA!$D:$D))), ROW(ISA!$D:$D)) - 2} -> 0 | E6: {=LOOKUP(2,1/(NOT(ISBLANK(ISA!$E:$E))), ROW(ISA!$E:$E)) - 2} -> 0 | F6: {=LOOKUP(2,1/(NOT(ISBLANK(ISA!$F:$F))), ROW(ISA!$F:$F)) - 2} -> 0 | G6: {=LOOKUP(2,1/(NOT(ISBLANK(ISA!$G:$G))), ROW(ISA!$G:$G)) - 2} -> 0 | H6: {=LOOKUP(2,1/(NOT(ISBLANK(ISA!$H:$H))), ROW(ISA!$H:$H)) - 2} -> 0 | I6: {=LOOKUP(2,1/(NOT(ISBLANK(ISA!$I:$I))), ROW(ISA!$I:$I)) - 2} -> 0 | J6: {=LOOKUP(2,1/(NOT(ISBLANK(ISA!$J:$J))), ROW(ISA!$J:$J)) - 2} -> 0 | K6: {=LOOKUP(2,1/(NOT(ISBLANK(ISA!$K:$K))), ROW(ISA!$K:$K)) - 2} -> 0 | L6: {=LOOKUP(2,1/(NOT(ISBLANK(ISA!$L:$L))), ROW(ISA!$L:$L)) - 2} -> 0 | M6: {=LOOKUP(2,1/(NOT(ISBLANK(ISA!$M:$M))), ROW(ISA!$M:$M)) - 2} -> 0 | N6: {=LOOKUP(2,1/(NOT(ISBLANK(ISA!$N:$N))), ROW(ISA!$N:$N)) - 2} -> 0 | O6: {=LOOKUP(2,1/(NOT(ISBLANK(ISA!$O:$O))), ROW(ISA!$O:$O)) - 2} -> 0 | P6: {=LOOKUP(2,1/(NOT(ISBLANK(ISA!$P:$P))), ROW(ISA!$P:$P)) - 2} -> 0 | Q6: {=LOOKUP(2,1/(NOT(ISBLANK(ISA!$Q:$Q))), ROW(ISA!$Q:$Q)) - 2} -> 0 | R6: {=LOOKUP(2,1/(NOT(ISBLANK(ISA!$R:$R))), ROW(ISA!$R:$R)) - 2} -> 0 | S6: {=LOOKUP(2,1/(NOT(ISBLANK(ISA!$S:$S))), ROW(ISA!$S:$S)) - 2} -> 0 | T6: {=LOOKUP(2,1/(NOT(ISBLANK(ISA!$T:$T))), ROW(ISA!$T:$T)) - 2} -> 0 | U6: {=LOOKUP(2,1/(NOT(ISBLANK(ISA!$U:$U))), ROW(ISA!$U:$U)) - 2} -> 0 | V6: {=LOOKUP(2,1/(NOT(ISBLANK(ISA!$V:$V))), ROW(ISA!$V:$V)) - 2} -> 0 | W6: {=LOOKUP(2,1/(NOT(ISBLANK(ISA!$W:$W))), ROW(ISA!$W:$W)) - 2} -> 0 | X6: {=LOOKUP(2,1/(NOT(ISBLANK(ISA!$X:$X))), ROW(ISA!$X:$X)) - 2} -> 0 | Y6: {=LOOKUP(2,1/(NOT(ISBLANK(ISA!$Y:$Y))), ROW(ISA!$Y:$Y)) - 2} -> 0 | Z6: {=LOOKUP(2,1/(NOT(ISBLANK(ISA!$Z:$Z))), ROW(ISA!$Z:$Z)) - 2} -> 0 | AA6: {=LOOKUP(2,1/(NOT(ISBLANK(ISA!$AA:$AA))), ROW(ISA!$AA:$AA)) - 2} -> 0 | AB6: {=LOOKUP(2,1/(NOT(ISBLANK(ISA!$AB:$AB))), ROW(ISA!$AB:$AB)) - 2} -> 0
A7: v All mandatory fields MUST be completed using the values instructed.
A9: v You MUST complete conditional fields ONLY where the conditions stated apply.
A11: v The error validation formulas embedded within the template are a CUSTOMER SUPPORT TOOL to assist the data supplier when entering their information.
A13: v For each column, ROW 1 will turn red to indicate that there is an error within the data supplied for that specific column.
A15: v Validation will also provide the error count for that specific column (total number of fields containing errors) and the 1st error row number.
A17: v Once the field containing the 1st error has been corrected, the 1st error row number will update to indicate the next field error within that column (if applicable).
A19: v After all errors within a specific column have been corrected, row 1 for that column will cease to be red, indicating that there are no further recognised errors within that column.
A21: v Please note when entering information that the error validation has been designed as a CUSTOMER SUPPORT TOOL and is NOT able to identify ALL potential errors which would be identified in subsequent HMRC data processing.
A23: v Therefore please also refer to the GUIDANCE on ROW 1 of the template for further information on the requirements for supplying your data.
A25: v Please DO NOT change any data entry field formats or the original file format as this may affect the error validation.
A27: v If you are pasting your data onto the spreadsheet please ensure that you use the PASTE SPECIAL option and select VALUES to ensure that the original data entry field format is NOT overwritten.
A29: v Please be aware that due to the size and complexity of the error validation formulas, you may experience delays with the validation response when inputting & correcting data.
... A37: v Please see below the specific error validations for each individual data type/column.
B39: Data Error Validations (Columns A - AB)
B41: COLUMN A
B42: ISA Manager Reference
B44: WHAT DOES IT VALIDATE
B45: · Data supplied MATCHES 8 character specific length.
B46: · Data supplied BEGINS with Z.
B47: · Data supplied MATCHES required format ZNNNN/NN.
B48: · NO other characters are acceptable.
B49: · Data supplied does NOT contain blank spaces.
B52: COLUMN B
B53: ISA Manager's Name
B55: WHAT DOES IT VALIDATE
... B57: · Data supplied is NOT one of the following unacceptable data entries:
B59: SEE ABOVE | C59: SEE LINE ABOVE | D59: N/K | E59: N/A | F59: U/K
B60: DITTO | C60: NOT KNOWN | D60: UNKNOWN | E60: NOT APPLICABLE
B63: COLUMN C
B64: Tax Year
B66: WHAT DOES IT VALIDATE
B67: · Data supplied MATCHES 4 character specific length.
B68: · Data supplied BEGINS with the first 2 expected numerical characters i.e. 20.
B69: · Data supplied ONLY contains numerical characters.
B70: · NO other characters are acceptable.
B71: · Data supplied does NOT contain blank spaces.
B74: COLUMN D
B75: ISA/JISA Account Number
...
