Workbook
Name A.: IF('GUIDANCE v2.4'!$A$6 > 1, OFFSET(RPSRAS!$A$3,0,0,'GUIDANCE v2.4'!$A$6,1), OFFSET(RPSRAS!$A$3,0,0,3,1))
Name B.: IF('GUIDANCE v2.4'!$B$6 > 1, OFFSET(RPSRAS!$B$3,0,0,'GUIDANCE v2.4'!$B$6,1), OFFSET(RPSRAS!$B$3,0,0,3,1))
Name C.: IF('GUIDANCE v2.4'!$C$6 > 1, OFFSET(RPSRAS!$C$3,0,0,'GUIDANCE v2.4'!$C$6,1), OFFSET(RPSRAS!$C$3,0,0,3,1))
Name D.: IF('GUIDANCE v2.4'!$D$6 > 1, OFFSET(RPSRAS!$D$3,0,0,'GUIDANCE v2.4'!$D$6,1), OFFSET(RPSRAS!$D$3,0,0,3,1))
Name E.: IF('GUIDANCE v2.4'!$E$6 > 1, OFFSET(RPSRAS!$E$3,0,0,'GUIDANCE v2.4'!$E$6,1), OFFSET(RPSRAS!$E$3,0,0,3,1))
Name F.: IF('GUIDANCE v2.4'!$F$6 > 1, OFFSET(RPSRAS!$F$3,0,0,'GUIDANCE v2.4'!$F$6,1), OFFSET(RPSRAS!$F$3,0,0,3,1))
Name G.: IF('GUIDANCE v2.4'!$G$6 > 1, OFFSET(RPSRAS!$G$3,0,0,'GUIDANCE v2.4'!$G$6,1), OFFSET(RPSRAS!$G$3,0,0,3,1))
Name H.: IF('GUIDANCE v2.4'!$H$6 > 1, OFFSET(RPSRAS!$H$3,0,0,'GUIDANCE v2.4'!$H$6,1), OFFSET(RPSRAS!$H$3,0,0,3,1))
Name I.: IF('GUIDANCE v2.4'!$I$6 > 1, OFFSET(RPSRAS!$I$3,0,0,'GUIDANCE v2.4'!$I$6,1), OFFSET(RPSRAS!$I$3,0,0,3,1))
Name J.: IF('GUIDANCE v2.4'!$J$6 > 1, OFFSET(RPSRAS!$J$3,0,0,'GUIDANCE v2.4'!$J$6,1), OFFSET(RPSRAS!$J$3,0,0,3,1))
Name K.: IF('GUIDANCE v2.4'!$K$6 > 1, OFFSET(RPSRAS!$K$3,0,0,'GUIDANCE v2.4'!$K$6,1), OFFSET(RPSRAS!$K$3,0,0,3,1))
Name L.: IF('GUIDANCE v2.4'!$L$6 > 1, OFFSET(RPSRAS!$L$3,0,0,'GUIDANCE v2.4'!$L$6,1), OFFSET(RPSRAS!$L$3,0,0,3,1))
Name M.: IF('GUIDANCE v2.4'!$M$6 > 1, OFFSET(RPSRAS!$M$3,0,0,'GUIDANCE v2.4'!$M$6,1), OFFSET(RPSRAS!$M$3,0,0,3,1))
Name N.: IF('GUIDANCE v2.4'!$N$6 > 1, OFFSET(RPSRAS!$N$3,0,0,'GUIDANCE v2.4'!$N$6,1), OFFSET(RPSRAS!$N$3,0,0,3,1))
Name O.: IF('GUIDANCE v2.4'!$O$6 > 1, OFFSET(RPSRAS!$O$3,0,0,'GUIDANCE v2.4'!$O$6,1), OFFSET(RPSRAS!$O$3,0,0,3,1))
Name P.: IF('GUIDANCE v2.4'!$P$6 > 1, OFFSET(RPSRAS!$P$3,0,0,'GUIDANCE v2.4'!$P$6,1), OFFSET(RPSRAS!$P$3,0,0,3,1))
Name Q.: IF('GUIDANCE v2.4'!$Q$6 > 1, OFFSET(RPSRAS!$Q$3,0,0,'GUIDANCE v2.4'!$Q$6,1), OFFSET(RPSRAS!$Q$3,0,0,3,1))
Name R.: IF('GUIDANCE v2.4'!$R$6 > 1, OFFSET(RPSRAS!$R$3,0,0,'GUIDANCE v2.4'!$R$6,1), OFFSET(RPSRAS!$R$3,0,0,3,1))
Name S.: IF('GUIDANCE v2.4'!$S$6 > 1, OFFSET(RPSRAS!$S$3,0,0,'GUIDANCE v2.4'!$S$6,1), OFFSET(RPSRAS!$S$3,0,0,3,1))
Name T.: IF('GUIDANCE v2.4'!$T$6 > 1, OFFSET(RPSRAS!$T$3,0,0,'GUIDANCE v2.4'!$T$6,1), OFFSET(RPSRAS!$T$3,0,0,3,1))
Name U.: IF('GUIDANCE v2.4'!$U$6 > 1, OFFSET(RPSRAS!$U$3,0,0,'GUIDANCE v2.4'!$U$6,1), OFFSET(RPSRAS!$U$3,0,0,3,1))
Name V.: IF('GUIDANCE v2.4'!$V$6 > 1, OFFSET(RPSRAS!$V$3,0,0,'GUIDANCE v2.4'!$V$6,1), OFFSET(RPSRAS!$V$3,0,0,3,1))
Name W.: IF('GUIDANCE v2.4'!$W$6 > 1, OFFSET(RPSRAS!$W$3,0,0,'GUIDANCE v2.4'!$W$6,1), OFFSET(RPSRAS!$W$3,0,0,3,1))
Name X.: IF('GUIDANCE v2.4'!$X$6 > 1, OFFSET(RPSRAS!$X$3,0,0,'GUIDANCE v2.4'!$X$6,1), OFFSET(RPSRAS!$X$3,0,0,3,1))

Sheet RPSRAS
A1: {="Error Count: "&SUM(IF(ISBLANK(A.),0,IF((LEN(A.)<>8)+(ISERROR(SEARCH(LEFT(A.),"P")))+(1-(ISNUMBER(VALUE(MID(A.,2,1)))))+(1-(ISNUMBER(VALUE(MID(A.,3,1)))))+(1-(ISNUMBER(VALUE(MID(A.,4,1)))))+(1-(ISNUMBER(VALUE(MID(A.,5,1)))))+(MID(A.,6,1)<>"/")+(1-(ISNUMBER(VALUE(MID(A.,7,1)))))+(1-(ISNUMBER(VALUE(MID(A.,8,1)))))+ (1-(ISERROR(SEARCH("~~", A.))))+ (1-(ISERROR(SEARCH("~?", A.))))+ (1-(ISERROR(SEARCH("~*", A.)))),1,0)))&CHAR(10)&"1st Error Row: "&SMALL(IF(ISBLANK(A.),FALSE,IF((SIGN(LEN(A.)<>8)+(ISERROR(SEARCH(LEFT(A.),"P")))+(1-(ISNUMBER(VALUE(MID(A.,2,1)))))+(1-(ISNUMBER(VALUE(MID(A.,3,1)))))+(1-(ISNUMBER(VALUE(MID(A.,4,1)))))+(1-(ISNUMBER(VALUE(MID(A.,5,1)))))+(MID(A.,6,1)<>"/")+(1-(ISNUMBER(VALUE(MID(A.,7,1)))))+(1-(ISNUMBER(VALUE(MID(A.,8,1)))))+ (1-(ISERROR(SEARCH("~~", A.))))+ (1-(ISERROR(SEARCH("~?", A.))))+ (1-(ISERROR(SEARCH("~*", A.))))),ROW(A.),FALSE)),1)} -> #NUM! | B1: {="Error Count: "&SUM(IF(ISBLANK(B.),0, IF((LEN(B.)>50) + (TRIM(B.)="SEE ABOVE") + (TRIM(B.)="SEE LINE ABOVE") + (TRIM(B.)="N/K") + (TRIM(B.)="U/K")+ (TRIM(B.)="NOT APPLICABLE") + (TRIM(B.)="N/A") + (TRIM(B.)="DITTO") + (TRIM(B.)="NOT KNOWN") + (TRIM(B.)="UNKNOWN"),1,0))) & CHAR(10) & "1st Error Row: " & SMALL(IF(ISBLANK(B.),FALSE,IF((SIGN(LEN(B.)>50) + (TRIM(B.)="SEE ABOVE") + (TRIM(B.)="SEE LINE ABOVE") + (TRIM(B.)="N/K") + (TRIM(B.)="U/K")+ (TRIM(B.)="NOT APPLICABLE") + (TRIM(B.)="N/A") + (TRIM(B.)="DITTO") + (TRIM(B.)="NOT KNOWN") + (TRIM(B.)="UNKNOWN")),ROW(B.),FALSE)),1)} -> #NUM! | C1: {="Error Count: "&SUM(IF(ISBLANK(C.),0,IF((LEN(C.)<>4)+(ISERROR(SEARCH(LEFT(C.,2),"20")))+(1-(ISNUMBER(VALUE(MID(C.,3,1)))))+(1-(ISNUMBER(VALUE(MID(C.,4,1)))))+ (1-(ISERROR(SEARCH("~~", C.))))+ (1-(ISERROR(SEARCH("~?", C.))))+ (1-(ISERROR(SEARCH("~*", C.)))),1,0)))&CHAR(10)&"1st Error Row: "&SMALL(IF(ISBLANK(C.),FALSE,IF((SIGN(LEN(C.)<>4)+(ISERROR(SEARCH(LEFT(C.,2),"20")))+(1-(ISNUMBER(VALUE(MID(C.,3,1)))))+(1-(ISNUMBER(VALUE(MID(C.,4,1)))))+ (1-(ISERROR(SEARCH("~~", C.))))+ (1-(ISERROR(SEARCH("~?", C.))))+ (1-(ISERROR(SEARCH("~*", C.))))),ROW(C.),FALSE)),1)} -> #NUM! | D1: {="Error Count: "&SUM(IF(ISBLANK(D.),0,IF((LEN(D.)<>10)+(ISERROR(SEARCH(LEFT(D.),"0123456789")))+(1-(ISNUMBER(VALUE(MID(D.,2,1)))))+(1-(ISNUMBER(VALUE(MID(D.,3,1)))))+(1-(ISNUMBER(VALUE(MID(D.,4,1)))))+(1-(ISNUMBER(VALUE(MID(D.,5,1)))))+(1-(ISNUMBER(VALUE(MID(D.,6,1)))))+(1-(ISNUMBER(VALUE(MID(D.,7,1)))))+(1-(ISNUMBER(VALUE(MID(D.,8,1)))))+(MID(D.,9,1)<>"R")+(ISERROR(SEARCH(MID(D.,10,1),"abcdefghijklmnopqrstuvwxyz")))+ (1-(ISERROR(SEARCH("~~", D.))))+ (1-(ISERROR(SEARCH("~?", D.))))+ (1-(ISERROR(SEARCH("~*", D.)))),1,0)))&CHAR(10)&"1st Error Row: "&SMALL(IF(ISBLANK(D.),FALSE,IF((SIGN(LEN(D.)<>10)+(ISERROR(SEARCH(LEFT(D.),"0123456789")))+(1-(ISNUMBER(VALUE(MID(D.,2,1)))))+(1-(ISNUMBER(VALUE(MID(D.,3,1)))))+(1-(ISNUMBER(VALUE(MID(D.,4,1)))))+(1-(ISNUMBER(VALUE(MID(D.,5,1)))))+(1-(ISNUMBER(VALUE(MID(D.,6,1)))))+(1-(ISNUMBER(VALUE(MID(D.,7,1)))))+(1-(ISNUMBER(VALUE(MID(D.,8,1)))))+(MID(D.,9,1)<>"R")+(ISERROR(SEARCH(MID(D.,10,1),"abcdefghijklmnopqrstuvwxyz")))+ (1-(ISERROR(SEARCH("~~", D.))))+ (1-(ISERROR(SEARCH("~?", D.))))+ (1-(ISERROR(SEARCH("~*", D.))))),ROW(D.),FALSE)),1)} -> #NUM! | E1: {="Error Count: "&SUM(IF(ISBLANK(E.),0, IF((LEN(E.)>10) + (TRIM(E.)="SEE ABOVE") + (TRIM(E.)="SEE LINE ABOVE") + (TRIM(E.)="N/K") + (TRIM(E.)="U/K")+ (TRIM(E.)="NOT APPLICABLE") + (TRIM(E.)="N/A")+ (TRIM(E.)="DITTO") + (TRIM(E.)="NOT KNOWN") + (TRIM(E.)="UNKNOWN"),1,0))) & CHAR(10) & "1st Error Row: " & SMALL(IF(ISBLANK(E.),FALSE,IF((SIGN(LEN(E.)>10) + (TRIM(E.)="SEE ABOVE") + (TRIM(E.)="SEE LINE ABOVE") + (TRIM(E.)="N/K") + (TRIM(E.)="U/K")+ (TRIM(E.)="NOT APPLICABLE") + (TRIM(E.)="N/A")+ (TRIM(E.)="DITTO") + (TRIM(E.)="NOT KNOWN") + (TRIM(E.)="UNKNOWN")),ROW(E.),FALSE)),1)} -> #NUM! | F1: {="Error Count: "&SUM(IF(ISBLANK(F.),0, IF((LEN(F.)>50) + (TRIM(F.)="SEE ABOVE") + (TRIM(F.)="SEE LINE ABOVE") + (TRIM(F.)="N/K") + (TRIM(F.)="U/K")+ (TRIM(F.)="NOT APPLICABLE") + (TRIM(F.)="N/A")+ (TRIM(F.)="DITTO") + (TRIM(F.)="NOT KNOWN") + (TRIM(F.)="UNKNOWN"),1,0))) & CHAR(10) & "1st Error Row: " & SMALL(IF(ISBLANK(F.),FALSE,IF((SIGN(LEN(F.)>50) + (TRIM(F.)="SEE ABOVE") + (TRIM(F.)="SEE LINE ABOVE") + (TRIM(F.)="N/K") + (TRIM(F.)="U/K")+ (TRIM(F.)="NOT APPLICABLE") + (TRIM(F.)="N/A")+ (TRIM(F.)="DITTO") + (TRIM(F.)="NOT KNOWN") + (TRIM(F.)="UNKNOWN")),ROW(F.),FALSE)),1)} -> #NUM! | G1: {="Error Count: "&SUM(IF(ISBLANK(G.),0, IF((LEN(G.)>50) + (TRIM(G.)="SEE ABOVE") + (TRIM(G.)="SEE LINE ABOVE") + (TRIM(G.)="N/K") + (TRIM(G.)="U/K")+ (TRIM(G.)="NOT APPLICABLE") + (TRIM(G.)="N/A")+ (TRIM(G.)="DITTO") + (TRIM(G.)="NOT KNOWN") + (TRIM(G.)="UNKNOWN"),1,0))) & CHAR(10) & "1st Error Row: " & SMALL(IF(ISBLANK(G.),FALSE,IF((SIGN(LEN(G.)>50) + (TRIM(G.)="SEE ABOVE") + (TRIM(G.)="SEE LINE ABOVE") + (TRIM(G.)="N/K") + (TRIM(G.)="U/K")+ (TRIM(G.)="NOT APPLICABLE") + (TRIM(G.)="N/A")+ (TRIM(G.)="DITTO") + (TRIM(G.)="NOT KNOWN") + (TRIM(G.)="UNKNOWN")),ROW(G.),FALSE)),1)} -> #NUM! | H1: {="Error Count: "&SUM((IF(ISBLANK(H.),0,IF((LEN(H.)<8)+(LEN(H.)>9)+(ISERROR(SEARCH(LEFT(H.),"abceghjklmnoprstwxyz")))+(ISERROR(SEARCH(MID(H.,2,1),"abceghjklmnprstwxyz")))+(1-(ISNUMBER(VALUE(MID(H.,3,1)))))+(1-(ISNUMBER(VALUE(MID(H.,4,1)))))+(1-(ISNUMBER(VALUE(MID(H.,5,1)))))+(1-(ISNUMBER(VALUE(MID(H.,6,1)))))+(1-(ISNUMBER(VALUE(MID(H.,7,1)))))+(1-(ISNUMBER(VALUE(MID(H.,8,1)))))+(ISERROR(SEARCH(MID(H.,9,1),"abcd ")))+(1-(ISERROR(SEARCH("BG",LEFT(H.,2)))))+(1-(ISERROR(SEARCH("GB",LEFT(H.,2)))))+(1-(ISERROR(SEARCH("KN",LEFT(H.,2)))))+(1-(ISERROR(SEARCH("NK",LEFT(H.,2)))))+(1-(ISERROR(SEARCH("NT",LEFT(H.,2)))))+(1-(ISERROR(SEARCH("TN",LEFT(H.,2)))))+(1-(ISERROR(SEARCH("ZZ",LEFT(H.,2))))) + (1-(ISERROR(SEARCH("~~", H.))))+ (1-(ISERROR(SEARCH("~*", H.))))+ (1-(ISERROR(SEARCH("~?", H.)))),1,0))))&CHAR(10)&"1st Error Row: "&SMALL(IF(ISBLANK(H.),FALSE,IF((SIGN(LEN(H.)<8)+(LEN(H.)>9)+(ISERROR(SEARCH(LEFT(H.),"abceghjklmnoprstwxyz")))+(ISERROR(SEARCH(MID(H.,2,1),"abceghjklmnprstwxyz")))+(1-(ISNUMBER(VALUE(MID(H.,3,1)))))+(1-(ISNUMBER(VALUE(MID(H.,4,1)))))+(1-(ISNUMBER(VALUE(MID(H.,5,1)))))+(1-(ISNUMBER(VALUE(MID(H.,6,1)))))+(1-(ISNUMBER(VALUE(MID(H.,7,1)))))+(1-(ISNUMBER(VALUE(MID(H.,8,1)))))+(ISERROR(SEARCH(MID(H.,9,1),"abcd ")))+(1-(ISERROR(SEARCH("BG",LEFT(H.,2)))))+(1-(ISERROR(SEARCH("GB",LEFT(H.,2)))))+(1-(ISERROR(SEARCH("KN",LEFT(H.,2)))))+(1-(ISERROR(SEARCH("NK",LEFT(H.,2)))))+(1-(ISERROR(SEARCH("NT",LEFT(H.,2)))))+(1-(ISERROR(SEARCH("TN",LEFT(H.,2)))))+(1-(ISERROR(SEARCH("ZZ",LEFT(H.,2)))))+ (1-(ISERROR(SEARCH("~~", H.))))+ (1-(ISERROR(SEARCH("~*", H.))))+ (1-(ISERROR(SEARCH("~?", H.))))),ROW(H.),FALSE)),1)} -> #NUM! | I1: {="Error Count: "&SUM(IF(ISBLANK(I.),0, IF((LEN(I.)>100) + (TRIM(I.)="N/K") + (TRIM(I.)="N/A") + (TRIM(I.)="U/K") + (TRIM(I.)="DITTO") + (TRIM(I.)="NOT KNOWN") + (TRIM(I.)="UNKNOWN"),1,0))) & CHAR(10) & "1st Error Row: " & SMALL(IF(ISBLANK(I.),FALSE,IF((SIGN(LEN(I.)>100) + (TRIM(I.)="N/K") + (TRIM(I.)="N/A") + (TRIM(I.)="U/K") + (TRIM(I.)="DITTO") + (TRIM(I.)="NOT KNOWN") + (TRIM(I.)="UNKNOWN")),ROW(I.),FALSE)),1)} -> #NUM! | J1: {="Error Count: "&SUM(IF(ISBLANK(J.),0,IF((LEN(J.)>40)+(1-(ISERROR(SEARCH(CHAR(10),J.))))+(1-(ISERROR(SEARCH(CHAR(13),J.))))+(1-(ISERROR(SEARCH("@",J.))))+(1-(ISERROR(SEARCH("C/O",LEFT(J.,3)))))+(TRIM(J.)="GONE AWAY")+(TRIM(J.)="N/A")+(TRIM(J.)="NOT APPLICABLE")+(TRIM(J.)="SEE ABOVE")+(TRIM(J.)="SEE LINE ABOVE")+(TRIM(J.)="N/K")+(TRIM(J.)="DITTO")+(TRIM(J.)="NOT KNOWN")+(TRIM(J.)="UNKNOWN"),1,0)))&CHAR(10)&"1st Error Row: "&SMALL(IF(ISBLANK(J.),FALSE,IF((SIGN(LEN(J.)>40)+(1-(ISERROR(SEARCH(CHAR(10),J.))))+(1-(ISERROR(SEARCH(CHAR(13),J.))))+(1-(ISERROR(SEARCH("@",J.))))+(1-(ISERROR(SEARCH("C/O",LEFT(J.,3)))))+(TRIM(J.)="GONE AWAY")+(TRIM(J.)="N/A")+(TRIM(J.)="NOT APPLICABLE")+(TRIM(J.)="SEE ABOVE")+(TRIM(J.)="SEE LINE ABOVE")+(TRIM(J.)="N/K")+(TRIM(J.)="DITTO")+(TRIM(J.)="NOT KNOWN")+(TRIM(J.)="UNKNOWN")),ROW(J.),FALSE)),1)} -> #NUM! | K1: {="Error Count: "&SUM(IF(ISBLANK(K.),0,IF((LEN(K.)>40)+(1-(ISERROR(SEARCH(CHAR(10),K.))))+(1-(ISERROR(SEARCH(CHAR(13),K.))))+(1-(ISERROR(SEARCH("@",K.))))+(1-(ISERROR(SEARCH("C/O",LEFT(K.,3)))))+(TRIM(K.)="GONE AWAY")+(TRIM(K.)="N/A")+(TRIM(K.)="NOT APPLICABLE")+(TRIM(K.)="SEE ABOVE")+(TRIM(K.)="SEE LINE ABOVE")+(TRIM(K.)="N/K")+(TRIM(K.)="DITTO")+(TRIM(K.)="NOT KNOWN")+(TRIM(K.)="UNKNOWN"),1,0)))&CHAR(10)&"1st Error Row: "&SMALL(IF(ISBLANK(K.),FALSE,IF((SIGN(LEN(K.)>40)+(1-(ISERROR(SEARCH(CHAR(10),K.))))+(1-(ISERROR(SEARCH(CHAR(13),K.))))+(1-(ISERROR(SEARCH("@",K.))))+(1-(ISERROR(SEARCH("C/O",LEFT(K.,3)))))+(TRIM(K.)="GONE AWAY")+(TRIM(K.)="N/A")+(TRIM(K.)="NOT APPLICABLE")+(TRIM(K.)="SEE ABOVE")+(TRIM(K.)="SEE LINE ABOVE")+(TRIM(K.)="N/K")+(TRIM(K.)="DITTO")+(TRIM(K.)="NOT KNOWN")+(TRIM(K.)="UNKNOWN")),ROW(K.),FALSE)),1)} -> #NUM! | L1: {="Error Count: "&SUM(IF(ISBLANK(L.),0,IF((LEN(L.)>40)+(1-(ISERROR(SEARCH(CHAR(10),L.))))+(1-(ISERROR(SEARCH(CHAR(13),L.))))+(1-(ISERROR(SEARCH("@",L.))))+(1-(ISERROR(SEARCH("C/O",LEFT(L.,3)))))+(TRIM(L.)="GONE AWAY")+(TRIM(L.)="N/A")+(TRIM(L.)="NOT APPLICABLE")+(TRIM(L.)="SEE ABOVE")+(TRIM(L.)="SEE LINE ABOVE")+(TRIM(L.)="N/K")+(TRIM(L.)="DITTO")+(TRIM(L.)="NOT KNOWN")+(TRIM(L.)="UNKNOWN"),1,0)))&CHAR(10)&"1st Error Row: "&SMALL(IF(ISBLANK(L.),FALSE,IF((SIGN(LEN(L.)>40)+(1-(ISERROR(SEARCH(CHAR(10),L.))))+(1-(ISERROR(SEARCH(CHAR(13),L.))))+(1-(ISERROR(SEARCH("@",L.))))+(1-(ISERROR(SEARCH("C/O",LEFT(L.,3)))))+(TRIM(L.)="GONE AWAY")+(TRIM(L.)="N/A")+(TRIM(L.)="NOT APPLICABLE")+(TRIM(L.)="SEE ABOVE")+(TRIM(L.)="SEE LINE ABOVE")+(TRIM(L.)="N/K")+(TRIM(L.)="DITTO")+(TRIM(L.)="NOT KNOWN")+(TRIM(L.)="UNKNOWN")),ROW(L.),FALSE)),1)} -> #NUM! | M1: {="Error Count: "&SUM(IF(ISBLANK(M.),0,IF((LEN(M.)>40)+(1-(ISERROR(SEARCH(CHAR(10),M.))))+(1-(ISERROR(SEARCH(CHAR(13),M.))))+(1-(ISERROR(SEARCH("@",M.))))+(1-(ISERROR(SEARCH("C/O",LEFT(M.,3)))))+(TRIM(M.)="GONE AWAY")+(TRIM(M.)="N/A")+(TRIM(M.)="NOT APPLICABLE")+(TRIM(M.)="SEE ABOVE")+(TRIM(M.)="SEE LINE ABOVE")+(TRIM(M.)="N/K")+(TRIM(M.)="DITTO")+(TRIM(M.)="NOT KNOWN")+(TRIM(M.)="UNKNOWN"),1,0)))&CHAR(10)&"1st Error Row: "&SMALL(IF(ISBLANK(M.),FALSE,IF((SIGN(LEN(M.)>40)+(1-(ISERROR(SEARCH(CHAR(10),M.))))+(1-(ISERROR(SEARCH(CHAR(13),M.))))+(1-(ISERROR(SEARCH("@",M.))))+(1-(ISERROR(SEARCH("C/O",LEFT(M.,3)))))+(TRIM(M.)="GONE AWAY")+(TRIM(M.)="N/A")+(TRIM(M.)="NOT APPLICABLE")+(TRIM(M.)="SEE ABOVE")+(TRIM(M.)="SEE LINE ABOVE")+(TRIM(M.)="N/K")+(TRIM(M.)="DITTO")+(TRIM(M.)="NOT KNOWN")+(TRIM(M.)="UNKNOWN")),ROW(M.),FALSE)),1)} -> #NUM! | N1: {="Error Count: "&SUM(IF(ISBLANK(N.),0,IF((LEN(N.)>40)+(1-(ISERROR(SEARCH(CHAR(10),N.))))+(1-(ISERROR(SEARCH(CHAR(13),N.))))+(1-(ISERROR(SEARCH("@",N.))))+(1-(ISERROR(SEARCH("C/O",LEFT(N.,3)))))+(TRIM(N.)="GONE AWAY")+(TRIM(N.)="N/A")+(TRIM(N.)="NOT APPLICABLE")+(TRIM(N.)="SEE ABOVE")+(TRIM(N.)="SEE LINE ABOVE")+(TRIM(N.)="N/K")+(TRIM(N.)="DITTO")+(TRIM(N.)="NOT KNOWN")+(TRIM(N.)="UNKNOWN"),1,0)))&CHAR(10)&"1st Error Row: "&SMALL(IF(ISBLANK(N.),FALSE,IF((SIGN(LEN(N.)>40)+(1-(ISERROR(SEARCH(CHAR(10),N.))))+(1-(ISERROR(SEARCH(CHAR(13),N.))))+(1-(ISERROR(SEARCH("@",N.))))+(1-(ISERROR(SEARCH("C/O",LEFT(N.,3)))))+(TRIM(N.)="GONE AWAY")+(TRIM(N.)="N/A")+(TRIM(N.)="NOT APPLICABLE")+(TRIM(N.)="SEE ABOVE")+(TRIM(N.)="SEE LINE ABOVE")+(TRIM(N.)="N/K")+(TRIM(N.)="DITTO")+(TRIM(N.)="NOT KNOWN")+(TRIM(N.)="UNKNOWN")),ROW(N.),FALSE)),1)} -> #NUM! | O1: {="Error Count: "&SUM(IF(ISBLANK(O.),0, IF((LEN(O.)>8)+((ISERROR(SEARCH("0",O.)))*(ISERROR(SEARCH("1",O.)))*(ISERROR(SEARCH("2",O.)))*(ISERROR(SEARCH("3",O.)))*(ISERROR(SEARCH("4",O.)))*(ISERROR(SEARCH("5",O.)))*(ISERROR(SEARCH("6",O.)))*(ISERROR(SEARCH("7",O.)))*(ISERROR(SEARCH("8",O.)))*(ISERROR(SEARCH("9",O.))))+ (1-(ISERROR(SEARCH("~~", O.))))+(1-(ISERROR(SEARCH("~*",O.))))+(1-(ISERROR(SEARCH("~?",O.)))),1,0)))&CHAR(10)&"1st Error Row: "&SMALL(IF(ISBLANK(O.),FALSE,IF((SIGN(LEN(O.)>8)+((ISERROR(SEARCH("0",O.)))*(ISERROR(SEARCH("1",O.)))*(ISERROR(SEARCH("2",O.)))*(ISERROR(SEARCH("3",O.)))*(ISERROR(SEARCH("4",O.)))*(ISERROR(SEARCH("5",O.)))*(ISERROR(SEARCH("6",O.)))*(ISERROR(SEARCH("7",O.)))*(ISERROR(SEARCH("8",O.)))*(ISERROR(SEARCH("9",O.))))+ (1-(ISERROR(SEARCH("~~", O.))))+(1-(ISERROR(SEARCH("~*",O.))))+(1-(ISERROR(SEARCH("~?",O.))))),ROW(O.),FALSE)),1)} -> #NUM! | P1: {="Error Count: "&SUM(IF(ISBLANK(P.),0, IF((LEN(P.)<>8)+(ISERROR(SEARCH(LEFT(P.),"0123")))+(ISERROR(SEARCH(MID(P.,2,1),"0123456789")))+(ISERROR(SEARCH(MID(P.,3,1),"01")))+(ISERROR(SEARCH(MID(P.,4,1),"0123456789")))+(ISERROR(SEARCH(MID(P.,5,1),"12")))+(ISERROR(SEARCH(MID(P.,6,1),"0123456789")))+(ISERROR(SEARCH(MID(P.,7,1),"0123456789")))+(ISERROR(SEARCH(RIGHT(P.),"0123456789")))+ (1-(ISERROR(SEARCH("~~", P.))))+ (1-(ISERROR(SEARCH("~?", P.))))+ (1-(ISERROR(SEARCH("~*", P.)))),1,0)))&CHAR(10)&"1st Error Row: "&SMALL(IF(ISBLANK(P.),FALSE,IF((SIGN(LEN(P.)<>8)+(ISERROR(SEARCH(LEFT(P.),"0123")))+(ISERROR(SEARCH(MID(P.,2,1),"0123456789")))+(ISERROR(SEARCH(MID(P.,3,1),"01")))+(ISERROR(SEARCH(MID(P.,4,1),"0123456789")))+(ISERROR(SEARCH(MID(P.,5,1),"12")))+(ISERROR(SEARCH(MID(P.,6,1),"0123456789")))+(ISERROR(SEARCH(MID(P.,7,1),"0123456789")))+(ISERROR(SEARCH(RIGHT(P.),"0123456789")))+ (1-(ISERROR(SEARCH("~~", P.))))+ (1-(ISERROR(SEARCH("~?", P.))))+ (1-(ISERROR(SEARCH("~*", P.))))),ROW(P.),FALSE)),1)} -> #NUM! | Q1: {="Error Count: " & SUM(IF(ISBLANK(Q.),0,IF((LEN(Q.)<>1)+(ISERROR(SEARCH(LEFT(Q.),"MFUN")))+ (1-(ISERROR(SEARCH("~~", Q.))))+ (1-(ISERROR(SEARCH("~?", Q.))))+ (1-(ISERROR(SEARCH("~*", Q.)))),1,0))) & CHAR(10) & "1st Error Row: " & SMALL(IF(ISBLANK(Q.),FALSE, IF((SIGN(LEN(Q.)<>1)+(ISERROR(SEARCH(LEFT(Q.),"MFUN")))+ (1-(ISERROR(SEARCH("~~", Q.))))+ (1-(ISERROR(SEARCH("~?", Q.))))+ (1-(ISERROR(SEARCH("~*", Q.))))),ROW(Q.),FALSE)),1)} -> #NUM! | R1: {="Error Count: " & SUM(IF(ISBLANK(R.),0,IF((LEN(R.)<>1)+(ISERROR(SEARCH(LEFT(R.),"123456789")))+ (1-(ISERROR(SEARCH("~~", R.))))+ (1-(ISERROR(SEARCH("~?", R.))))+ (1-(ISERROR(SEARCH("~*", R.)))),1,0))) & CHAR(10) & "1st Error Row: " & SMALL(IF(ISBLANK(R.),FALSE, IF((SIGN(LEN(R.)<>1)+(ISERROR(SEARCH(LEFT(R.),"123456789")))+ (1-(ISERROR(SEARCH("~~", R.))))+ (1-(ISERROR(SEARCH("~?", R.))))+ (1-(ISERROR(SEARCH("~*", R.))))),ROW(R.),FALSE)),1)} -> #NUM! | S1: {="Error Count: " & SUM(IF(ISBLANK(S.),0,IF((LEN(S.)<>1)+(ISERROR(SEARCH(LEFT(S.),"CS ")))+ (1-(ISERROR(SEARCH("~~", S.))))+ (1-(ISERROR(SEARCH("~?", S.))))+ (1-(ISERROR(SEARCH("~*", S.)))),1,0))) & CHAR(10) & "1st Error Row: " & SMALL(IF(ISBLANK(S.),FALSE, IF((SIGN(LEN(S.)<>1)+(ISERROR(SEARCH(LEFT(S.),"CS ")))+ (1-(ISERROR(SEARCH("~~", S.))))+ (1-(ISERROR(SEARCH("~?", S.))))+ (1-(ISERROR(SEARCH("~*", S.))))),ROW(S.),FALSE)),1)} -> #NUM! | T1: {="Error Count: "&SUM(IF(ISBLANK(T.),0,IF((ISNUMBER(T.)*((T.)>999999))+(ISTEXT(T.)*(LEN(T.)>6))+(ISTEXT(T.)*(1-(ISERROR(SEARCH(".", T.)))))+(ISERROR(SEARCH(LEFT(T.),"0123456789")))+(ISERROR(SEARCH(RIGHT(T.),"0123456789")))+(1-(ISNUMBER(VALUE(T.))))+ (1-(ISERROR(SEARCH(" ", T.))))+ (1-(ISERROR(SEARCH(",", T.))))+ (1-(ISERROR(SEARCH("~~", T.))))+ (1-(ISERROR(SEARCH("~?", T.))))+ (1-(ISERROR(SEARCH("~*", T.)))),1,0)))&CHAR(10)&"1st Error Row: "&SMALL(IF(ISBLANK(T.),FALSE,IF((SIGN(ISNUMBER(T.)*((T.)>999999))+(ISTEXT(T.)*(LEN(T.)>6))+(ISTEXT(T.)*(1-(ISERROR(SEARCH(".", T.)))))+(ISERROR(SEARCH(LEFT(T.),"0123456789")))+(ISERROR(SEARCH(RIGHT(T.),"0123456789")))+(1-(ISNUMBER(VALUE(T.))))+ (1-(ISERROR(SEARCH(" ", T.))))+ (1-(ISERROR(SEARCH(",", T.))))+ (1-(ISERROR(SEARCH("~~", T.))))+ (1-(ISERROR(SEARCH("~?", T.))))+ (1-(ISERROR(SEARCH("~*", T.))))),ROW(T.),FALSE)),1)} -> #NUM! | U1: {="Error Count: "&SUM(IF(ISBLANK(U.),0,IF((ISNUMBER(U.)*((U.)>999999))+(ISTEXT(U.)*(LEN(U.)>6))+(ISTEXT(U.)*(1-(ISERROR(SEARCH(".", U.)))))+(ISERROR(SEARCH(LEFT(U.),"0123456789")))+(ISERROR(SEARCH(RIGHT(U.),"0123456789")))+(1-(ISNUMBER(VALUE(U.))))+ (1-(ISERROR(SEARCH(" ", U.))))+ (1-(ISERROR(SEARCH(",", U.))))+ (1-(ISERROR(SEARCH("~~", U.))))+ (1-(ISERROR(SEARCH("~?", U.))))+ (1-(ISERROR(SEARCH("~*", U.)))),1,0)))&CHAR(10)&"1st Error Row: "&SMALL(IF(ISBLANK(U.),FALSE,IF((SIGN(ISNUMBER(U.)*((U.)>999999))+(ISTEXT(U.)*(LEN(U.)>6))+(ISTEXT(U.)*(1-(ISERROR(SEARCH(".", U.)))))+(ISERROR(SEARCH(LEFT(U.),"0123456789")))+(ISERROR(SEARCH(RIGHT(U.),"0123456789")))+(1-(ISNUMBER(VALUE(U.))))+ (1-(ISERROR(SEARCH(" ", U.))))+ (1-(ISERROR(SEARCH(",", U.))))+ (1-(ISERROR(SEARCH("~~", U.))))+ (1-(ISERROR(SEARCH("~?", U.))))+ (1-(ISERROR(SEARCH("~*", U.))))),ROW(U.),FALSE)),1)} -> #NUM! | V1: {="Error Count: "&SUM(IF(ISBLANK(V.),0,IF((ISNUMBER(V.)*((V.)>99999999))+(ISTEXT(V.)*(LEN(V.)>8))+(ISTEXT(V.)*(1-(ISERROR(SEARCH(".", V.)))))+(ISERROR(SEARCH(LEFT(V.),"0123456789")))+(ISERROR(SEARCH(RIGHT(V.),"0123456789")))+(1-(ISNUMBER(VALUE(V.))))+ (1-(ISERROR(SEARCH(" ", V.))))+ (1-(ISERROR(SEARCH(",", V.))))+ (1-(ISERROR(SEARCH("~~", V.))))+ (1-(ISERROR(SEARCH("~?", V.))))+ (1-(ISERROR(SEARCH("~*", V.)))),1,0)))&CHAR(10)&"1st Error Row: "&SMALL(IF(ISBLANK(V.),FALSE,IF((SIGN(ISNUMBER(V.)*((V.)>99999999))+(ISTEXT(V.)*(LEN(V.)>8))+(ISTEXT(V.)*(1-(ISERROR(SEARCH(".", V.)))))+(ISERROR(SEARCH(LEFT(V.),"0123456789")))+(ISERROR(SEARCH(RIGHT(V.),"0123456789")))+(1-(ISNUMBER(VALUE(V.))))+ (1-(ISERROR(SEARCH(" ", V.))))+ (1-(ISERROR(SEARCH(",", V.))))+ (1-(ISERROR(SEARCH("~~", V.))))+ (1-(ISERROR(SEARCH("~?", V.))))+ (1-(ISERROR(SEARCH("~*", V.))))),ROW(V.),FALSE)),1)} -> #NUM! | W1: {="Error Count: "&SUM(IF(ISBLANK(W.),0,IF((ISNUMBER(W.)*((W.)>99999999))+(ISTEXT(W.)*(LEN(W.)>8))+(ISTEXT(W.)*(1-(ISERROR(SEARCH(".", W.)))))+(ISERROR(SEARCH(LEFT(W.),"0123456789")))+(ISERROR(SEARCH(RIGHT(W.),"0123456789")))+(1-(ISNUMBER(VALUE(W.))))+ (1-(ISERROR(SEARCH(" ", W.))))+ (1-(ISERROR(SEARCH(",", W.))))+ (1-(ISERROR(SEARCH("~~", W.))))+ (1-(ISERROR(SEARCH("~?", W.))))+ (1-(ISERROR(SEARCH("~*", W.)))),1,0)))&CHAR(10)&"1st Error Row: "&SMALL(IF(ISBLANK(W.),FALSE,IF((SIGN(ISNUMBER(W.)*((W.)>99999999))+(ISTEXT(W.)*(LEN(W.)>8))+(ISTEXT(W.)*(1-(ISERROR(SEARCH(".", W.)))))+(ISERROR(SEARCH(LEFT(W.),"0123456789")))+(ISERROR(SEARCH(RIGHT(W.),"0123456789")))+(1-(ISNUMBER(VALUE(W.))))+ (1-(ISERROR(SEARCH(" ", W.))))+ (1-(ISERROR(SEARCH(",", W.))))+ (1-(ISERROR(SEARCH("~~", W.))))+ (1-(ISERROR(SEARCH("~?", W.))))+ (1-(ISERROR(SEARCH("~*", W.))))),ROW(W.),FALSE)),1)} -> #NUM! | X1: {="Error Count: "&SUM(IF(ISBLANK(X.),0, IF((LEN(X.)<>8)+(ISERROR(SEARCH(LEFT(X.),"0123")))+(ISERROR(SEARCH(MID(X.,2,1),"0123456789")))+(ISERROR(SEARCH(MID(X.,3,1),"01")))+(ISERROR(SEARCH(MID(X.,4,1),"0123456789")))+(ISERROR(SEARCH(MID(X.,5,1),"12")))+(ISERROR(SEARCH(MID(X.,6,1),"0123456789")))+(ISERROR(SEARCH(MID(X.,7,1),"0123456789")))+(ISERROR(SEARCH(RIGHT(X.),"0123456789")))+ (1-(ISERROR(SEARCH("~~", X.))))+ (1-(ISERROR(SEARCH("~?", X.))))+ (1-(ISERROR(SEARCH("~*", X.)))),1,0)))&CHAR(10)&"1st Error Row: "&SMALL(IF(ISBLANK(X.),FALSE,IF((SIGN(LEN(X.)<>8)+(ISERROR(SEARCH(LEFT(X.),"0123")))+(ISERROR(SEARCH(MID(X.,2,1),"0123456789")))+(ISERROR(SEARCH(MID(X.,3,1),"01")))+(ISERROR(SEARCH(MID(X.,4,1),"0123456789")))+(ISERROR(SEARCH(MID(X.,5,1),"12")))+(ISERROR(SEARCH(MID(X.,6,1),"0123456789")))+(ISERROR(SEARCH(MID(X.,7,1),"0123456789")))+(ISERROR(SEARCH(RIGHT(X.),"0123456789")))+ (1-(ISERROR(SEARCH("~~", X.))))+ (1-(ISERROR(SEARCH("~?", X.))))+ (1-(ISERROR(SEARCH("~*", X.))))),ROW(X.),FALSE)),1)} -> #NUM!
A2: {=IFERROR("Pension Scheme Administrator Reference" & CHAR(10) & "8 Characters" & CHAR(10) & "MANDATORY FIELD"& CHAR(10) & "(" &SUM(IF((($A$3:$A$3)=""),1,0)) & " Not Completed)","Pension Scheme Administrator Reference" & CHAR(10) & "8 Characters" & CHAR(10) & "MANDATORY FIELD")} -> Pension Scheme Administrator Reference 8 Characters MANDATORY FIELD (1 Not Completed) | B2: {=IFERROR("Pension Scheme/Administrator's Name" & CHAR(10) & "Max. 50 Characters" & CHAR(10) & "MANDATORY FIELD"& CHAR(10) & "(" &SUM(IF((($B$3:$B$3)=""),1,0)) & " Not Completed)","Pension Scheme/Administrator's Name" & CHAR(10) & "Max. 50 Characters" & CHAR(10) & "MANDATORY FIELD")} -> Pension Scheme/Administrator's Name Max. 50 Characters MANDATORY FIELD (1 Not Completed) | C2: {=IFERROR("Tax Year" & CHAR(10) & "4 Characters" & CHAR(10) & "MANDATORY FIELD"& CHAR(10) & "(" &SUM(IF((($C$3:$C$3)=""),1,0)) & " Not Completed)","Tax Year" & CHAR(10) & "4 Characters" & CHAR(10) & "MANDATORY FIELD")} -> Tax Year 4 Characters MANDATORY FIELD (1 Not Completed) | D2: {=IFERROR("Pension Scheme Tax Reference (PSTR)" & CHAR(10) & "10 Characters" & CHAR(10) & "MANDATORY FIELD"& CHAR(10) & "(" &SUM(IF((($D$3:$D$1048576)="")*((($E$3:$E$1048576)<>"")+(($F$3:$F$1048576)<>"")),1,0)) & " Not Completed)","Pension Scheme Tax Reference (PSTR)" & CHAR(10) & "10 Characters" & CHAR(10) & "MANDATORY FIELD")} -> Pension Scheme Tax Reference (PSTR) 10 Characters MANDATORY FIELD (0 Not Completed) | E2: {=IFERROR("Member's Title" & CHAR(10) & "Max. 10 Characters" & CHAR(10) & "MANDATORY FIELD"& CHAR(10) & "(" &SUM(IF((($E$3:$E$1048576)="")*((($D$3:$D$1048576)<>"")+(($F$3:$F$1048576)<>"")),1,0)) & " Not Completed)","Member's Title" & CHAR(10) & "Max. 10 Characters" & CHAR(10) & "MANDATORY FIELD")} -> Member's Title Max. 10 Characters MANDATORY FIELD (0 Not Completed) | F2: {=IFERROR("Member's Forename(s)" & CHAR(10) & "Max. 50 Characters" & CHAR(10) & "MANDATORY FIELD"& CHAR(10) & "(" &SUM(IF((($F$3:$F$1048576)="")*((($E$3:$E$1048576)<>"")+(($G$3:$G$1048576)<>"")),1,0)) & " Not Completed)","Member's Forename(s)" & CHAR(10) & "Max. 50 Characters" & CHAR(10) & "MANDATORY FIELD")} -> Member's Forename(s) Max. 50 Characters MANDATORY FIELD (0 Not Completed) | G2: {=IFERROR("Member's Surname" & CHAR(10) & "Max. 50 Characters" & CHAR(10) & "MANDATORY FIELD"& CHAR(10) & "(" &SUM(IF((($G$3:$G$1048576)="")*((($F$3:$F$1048576)<>"")+(($J$3:$J$1048576)<>"")),1,0)) & " Not Completed)","Member's Surname" & CHAR(10) & "Max. 50 Characters" & CHAR(10) & "MANDATORY FIELD")} -> Member's Surname Max. 50 Characters MANDATORY FIELD (0 Not Completed) | H2: Member's National Insurance Number (NINO) 8-9 Characters CONDITIONAL FIELD | I2: Reason for no National Insurance Number (NINO) Max. 100 Characters CONDITIONAL FIELD | J2: {=IFERROR("Member's Address Line 1" & CHAR(10) & "Max. 40 Characters" & CHAR(10) & "MANDATORY FIELD"& CHAR(10) & "(" &SUM(IF((($J$3:$J$1048576)="")*((($G$3:$G$1048576)<>"")+(($K$3:$K$1048576)<>"")),1,0)) & " Not Completed)","Member's Address Line 1" & CHAR(10) & "Max. 40 Characters" & CHAR(10) & "MANDATORY FIELD")} -> Member's Address Line 1 Max. 40 Characters MANDATORY FIELD (0 Not Completed) | K2: {=IFERROR("Member's Address Line 2" & CHAR(10) & "Max. 40 Characters" & CHAR(10) & "MANDATORY FIELD"& CHAR(10) & "(" &SUM(IF((($K$3:$K$1048576)="")*((($J$3:$J$1048576)<>"")+(($P$3:$P$1048576)<>"")),1,0)) & " Not Completed)","Member's Address Line 2" & CHAR(10) & "Max. 40 Characters" & CHAR(10) & "MANDATORY FIELD")} -> Member's Address Line 2 Max. 40 Characters MANDATORY FIELD (0 Not Completed) | L2: Member's Address Line 3 Max. 40 Characters CONDITIONAL FIELD | M2: Member's Address Line 4 Max. 40 Characters CONDITIONAL FIELD | N2: Member's Address Line 5 Max. 40 Characters CONDITIONAL FIELD | O2: Member's Postcode Max. 8 Characters CONDITIONAL FIELD | P2: {=IFERROR("Member's Date of Birth" & CHAR(10) & "8 Characters" & CHAR(10) & "MANDATORY FIELD"& CHAR(10) & "(" &SUM(IF((($P$3:$P$1048576)="")*((($K$3:$K$1048576)<>"")+(($Q$3:$Q$1048576)<>"")),1,0)) & " Not Completed)","Member's Date of Birth" & CHAR(10) & "8 Characters" & CHAR(10) & "MANDATORY FIELD")} -> Member's Date of Birth 8 Characters MANDATORY FIELD (0 Not Completed) | Q2: {=IFERROR("Member's Gender" & CHAR(10) & "1 Character" & CHAR(10) & "MANDATORY FIELD"& CHAR(10) & "(" &SUM(IF((($Q$3:$Q$1048576)="")*((($P$3:$P$1048576)<>"")+(($R$3:$R$1048576)<>"")),1,0)) & " Not Completed)","Member's Gender" & CHAR(10) & "1 Character" & CHAR(10) & "MANDATORY FIELD")} -> Member's Gender 1 Character MANDATORY FIELD (0 Not Completed) | R2: {=IFERROR("Member's Status" & CHAR(10) & "1 Character" & CHAR(10) & "MANDATORY FIELD"& CHAR(10) & "(" &SUM(IF((($R$3:$R$1048576)="")*((($Q$3:$Q$1048576)<>"")+(($W$3:$W$1048576)<>"")),1,0)) & " Not Completed)","Member's Status" & CHAR(10) & "1 Character" & CHAR(10) & "MANDATORY FIELD")} -> Member's Status 1 Character MANDATORY FIELD (0 Not Completed) | S2: Rate of Relief 1 Character MANDATORY FIELD | T2: Individual Contribution Max. 6 Characters CONDTIONAL FIELD | U2: Life Assurance Premium Contribution Max. 6 Characters CONDTIONAL FIELD | V2: Total Amount of Transfer Payments Received Max. 8 Characters CONDTIONAL FIELD | W2: {=IFERROR("Value of Member's Fund" & CHAR(10) & "Max. 8 Characters" & CHAR(10) & "MANDATORY FIELD"& CHAR(10) & "(" &SUM(IF((($W$3:$W$1048576)="")*((($R$3:$R$1048576)<>"")+(($X$3:$X$1048576)<>"")),1,0)) & " Not Completed)","Value of Member's Fund" & CHAR(10) & "Max. 8 Characters" & CHAR(10) & "MANDATORY FIELD")} -> Value of Member's Fund Max. 8 Characters MANDATORY FIELD (0 Not Completed) | X2: {=IFERROR("Date of Fund Valuation" & CHAR(10) & "8 Characters" & CHAR(10) & "MANDATORY FIELD"& CHAR(10) & "(" &SUM(IF((($X$3:$X$1048576)="")*((($R$3:$R$1048576)<>"")+(($W$3:$W$1048576)<>"")),1,0)) & " Not Completed)","Date of Fund Valuation" & CHAR(10) & "8 Characters" & CHAR(10) & "MANDATORY FIELD")} -> Date of Fund Valuation 8 Characters MANDATORY FIELD (0 Not Completed)

Sheet GUIDANCE v2.4
D1: SPREADSHEET TEMPLATE ERROR VALIDATION GUIDANCE version 2.4
A6: {=LOOKUP(2,1/(NOT(ISBLANK(RPSRAS!$A:$A))), ROW(RPSRAS!$A:$A)) - 2} -> 0 | B6: {=LOOKUP(2,1/(NOT(ISBLANK(RPSRAS!$B:$B))), ROW(RPSRAS!$B:$B)) - 2} -> 0 | C6: {=LOOKUP(2,1/(NOT(ISBLANK(RPSRAS!$C:$C))), ROW(RPSRAS!$C:$C)) - 2} -> 0 | D6: {=LOOKUP(2,1/(NOT(ISBLANK(RPSRAS!$D:$D))), ROW(RPSRAS!$D:$D)) - 2} -> 0 | E6: {=LOOKUP(2,1/(NOT(ISBLANK(RPSRAS!$E:$E))), ROW(RPSRAS!$E:$E)) - 2} -> 0 | F6: {=LOOKUP(2,1/(NOT(ISBLANK(RPSRAS!$F:$F))), ROW(RPSRAS!$F:$F)) - 2} -> 0 | G6: {=LOOKUP(2,1/(NOT(ISBLANK(RPSRAS!$G:$G))), ROW(RPSRAS!$G:$G)) - 2} -> 0 | H6: {=LOOKUP(2,1/(NOT(ISBLANK(RPSRAS!$H:$H))), ROW(RPSRAS!$H:$H)) - 2} -> 0 | I6: {=LOOKUP(2,1/(NOT(ISBLANK(RPSRAS!$I:$I))), ROW(RPSRAS!$I:$I)) - 2} -> 0 | J6: {=LOOKUP(2,1/(NOT(ISBLANK(RPSRAS!$J:$J))), ROW(RPSRAS!$J:$J)) - 2} -> 0 | K6: {=LOOKUP(2,1/(NOT(ISBLANK(RPSRAS!$K:$K))), ROW(RPSRAS!$K:$K)) - 2} -> 0 | L6: {=LOOKUP(2,1/(NOT(ISBLANK(RPSRAS!$L:$L))), ROW(RPSRAS!$L:$L)) - 2} -> 0 | M6: {=LOOKUP(2,1/(NOT(ISBLANK(RPSRAS!$M:$M))), ROW(RPSRAS!$M:$M)) - 2} -> 0 | N6: {=LOOKUP(2,1/(NOT(ISBLANK(RPSRAS!$N:$N))), ROW(RPSRAS!$N:$N)) - 2} -> 0 | O6: {=LOOKUP(2,1/(NOT(ISBLANK(RPSRAS!$O:$O))), ROW(RPSRAS!$O:$O)) - 2} -> 0 | P6: {=LOOKUP(2,1/(NOT(ISBLANK(RPSRAS!$P:$P))), ROW(RPSRAS!$P:$P)) - 2} -> 0 | Q6: {=LOOKUP(2,1/(NOT(ISBLANK(RPSRAS!$Q:$Q))), ROW(RPSRAS!$Q:$Q)) - 2} -> 0 | R6: {=LOOKUP(2,1/(NOT(ISBLANK(RPSRAS!$R:$R))), ROW(RPSRAS!$R:$R)) - 2} -> 0 | S6: {=LOOKUP(2,1/(NOT(ISBLANK(RPSRAS!$S:$S))), ROW(RPSRAS!$S:$S)) - 2} -> 0 | T6: {=LOOKUP(2,1/(NOT(ISBLANK(RPSRAS!$T:$T))), ROW(RPSRAS!$T:$T)) - 2} -> 0 | U6: {=LOOKUP(2,1/(NOT(ISBLANK(RPSRAS!$U:$U))), ROW(RPSRAS!$U:$U)) - 2} -> 0 | V6: {=LOOKUP(2,1/(NOT(ISBLANK(RPSRAS!$V:$V))), ROW(RPSRAS!$V:$V)) - 2} -> 0 | W6: {=LOOKUP(2,1/(NOT(ISBLANK(RPSRAS!$W:$W))), ROW(RPSRAS!$W:$W)) - 2} -> 0 | X6: {=LOOKUP(2,1/(NOT(ISBLANK(RPSRAS!$X:$X))), ROW(RPSRAS!$X:$X)) - 2} -> 0
A7: v All mandatory fields MUST be completed using the values instructed. You MUST complete conditional fields ONLY where the conditions stated ARE applicable.
A9: v The error validation formulas embedded within the template are a CUSTOMER SUPPORT TOOL to assist the data supplier when entering their information.
A11: v For each column, ROW 1 will turn red to indicate that there is an error within the data supplied for that specific column.
A13: v Validation will also provide the error count for that specific column (total number of fields containing errors) and the 1st error row number.
A15: v Once the field containing the 1st error has been corrected, the 1st error row number will update to indicate the next field error within that column (if applicable).
A17: v After all errors within a specific column have been corrected, row 1 for that column will cease to be red, indicating that there are no further recognised errors within that column.
A19: v Please note when entering information that the error validation has been designed as a CUSTOMER SUPPORT TOOL and is NOT able to identify ALL potential errors which would be identified in subsequent HMRC data processing.
A21: v Therefore please also refer to the GUIDANCE on ROW 1 of the template for further information on the requirements for supplying your data.
A23: v Please DO NOT change any data entry field formats or the original file format as this may affect the error validation.
A25: v If you are pasting your data onto the spreadsheet please ensure that you use the PASTE SPECIAL option and select VALUES to ensure that the original data entry field format is NOT overwritten.
A27: v Please be aware that due to the size and complexity of the error validation formulas, you may experience delays with the validation response when inputting & correcting data.
A29: v Please ensure that your return IS submitted using the downloaded original spreadsheet template and NOT copied onto a blank excel spreadsheet as this may impact HMRC processing.
... A35: v Please see below the specific error validations for each individual data type/column.
B37: Data Error Validations (Columns A - X)
B39: COLUMN A
B40: Pension Scheme Administrator Reference
B42: WHAT DOES IT VALIDATE
B43: · Data supplied MATCHES 8 character specific length.
B44: · Data supplied BEGINS with P.
B45: · Data supplied MATCHES required format PNNNN/NN.
B46: · NO other characters are acceptable.
B47: · Data supplied does NOT contain blank spaces.
B50: COLUMN B
B51: Pension Scheme/Administrator's Name
B53: WHAT DOES IT VALIDATE
... B55: · Data supplied is NOT one of the following unacceptable data entries:
B57: SEE ABOVE | C57: SEE LINE ABOVE | D57: N/K | E57: N/A | F57: U/K
B58: DITTO | C58: NOT KNOWN | D58: UNKNOWN | E58: NOT APPLICABLE
B61: COLUMN C
B62: Tax Year
B64: WHAT DOES IT VALIDATE
B65: · Data supplied MATCHES 4 character specific length.
B66: · Data supplied BEGINS with the first 2 expected numerical characters i.e. 20.
B67: · Data supplied ONLY contains numerical characters.
B68: · NO other characters are acceptable.
B69: · Data supplied does NOT contain blank spaces.
B72: COLUMN D
B73: Pension Scheme Tax Reference (PSTR)
...
